Workbook

Sheet CONSULTA
B2: CONTROL DE MANTENIMIENTO PREVENTIVO
B4: EQUIPO | C4: 04101 - VL001- TRIMOTO MAVILA 1 - CAMPO | S4: =MATCH(LEFT(C4,5),EQUIPOS!$B$3:$B$18,0)+2 -> 3
B6: CÓDIGO | C6: =IF(INDEX(EQUIPOS!B:B,$S$4)="","",INDEX(EQUIPOS!B:B,$S$4)) -> 04101 | E6: CONTROL | F6: =IF(INDEX(EQUIPOS!G:G,$S$4)="","",INDEX(EQUIPOS!G:G,$S$4)) -> KM | G6: ÚLTIMO MANT. | I6: =IF(INDEX(EQUIPOS!K:K,$S$4)="","",INDEX(EQUIPOS!K:K,$S$4)) -> SIN REGISTRO | M6: PRÓXIMO MANT. | N6: =IF(INDEX(EQUIPOS!N:N,$S$4)="","",INDEX(EQUIPOS!N:N,$S$4)) -> PM1 - 1000 KM
B7: ÁREA | C7: =IF(INDEX(EQUIPOS!D:D,$S$4)="","",INDEX(EQUIPOS!D:D,$S$4)) -> RIEGO | E7: INTERVALO | F7: =IF(INDEX(EQUIPOS!H:H,$S$4)="","",INDEX(EQUIPOS!H:H,$S$4)) -> 1000 | G7: FECHA ÚLTIMO | I7: =IF(INDEX(EQUIPOS!L:L,$S$4)="","",INDEX(EQUIPOS!L:L,$S$4)) | M7: PRÓXIMO A | N7: =IF(INDEX(EQUIPOS!O:O,$S$4)="","",IF($F$6="MESES",INDEX(EQUIPOS!O:O,$S$4),TEXT(INDEX(EQUIPOS!O:O,$S$4),"#,##0")&" "&$F$6))
B8: CRITICIDAD | C8: =IF(INDEX(EQUIPOS!E:E,$S$4)="","",INDEX(EQUIPOS!E:E,$S$4)) -> BAJO | E8: LECTURA ACTUAL | F8: =IF(INDEX(EQUIPOS!I:I,$S$4)="","",INDEX(EQUIPOS!I:I,$S$4)) | G8: LECTURA ÚLTIMO | I8: =IF(INDEX(EQUIPOS!M:M,$S$4)="","",INDEX(EQUIPOS!M:M,$S$4)) | M8: FALTA | N8: =IF(INDEX(EQUIPOS!P:P,$S$4)="","",TEXT(INDEX(EQUIPOS!P:P,$S$4),"#,##0")&IF($F$6="MESES"," DÍAS"," "&$F$6))
B9: PLAN | C9: =IF(INDEX(EQUIPOS!F:F,$S$4)="","",INDEX(EQUIPOS!F:F,$S$4)) -> TRIMOTO MAVILA CARGO 250 | E9: FECHA LECTURA | F9: =IF(INDEX(EQUIPOS!J:J,$S$4)="","",INDEX(EQUIPOS!J:J,$S$4)) | M9: ESTADO | N9: =IF(INDEX(EQUIPOS!Q:Q,$S$4)="","",INDEX(EQUIPOS!Q:Q,$S$4)) -> SIN REGISTRO
B11: OBSERVACIONES DE MANTENIMIENTOS ANTERIORES
B12: FECHA | C12: MANTENIMIENTO | E12: OBSERVACIÓN
B13: =IF($S13=0,"",INDEX(REGISTRO!B:B,$S13)) | C13: =IF($S13=0,"",INDEX(REGISTRO!H:H,$S13)) | E13: =IF($S13=0,"",INDEX(REGISTRO!M:M,$S13)) | S13: =IFERROR(MATCH($C$6&"|"&(COUNTIFS(REGISTRO!$C$3:$C$2002,$C$6,REGISTRO!$M$3:$M$2002,"<>")-0),REGISTRO!$O:$O,0),0) -> 0
B14: =IF($S14=0,"",INDEX(REGISTRO!B:B,$S14)) | C14: =IF($S14=0,"",INDEX(REGISTRO!H:H,$S14)) | E14: =IF($S14=0,"",INDEX(REGISTRO!M:M,$S14)) | S14: =IFERROR(MATCH($C$6&"|"&(COUNTIFS(REGISTRO!$C$3:$C$2002,$C$6,REGISTRO!$M$3:$M$2002,"<>")-1),REGISTRO!$O:$O,0),0) -> 0
B15: =IF($S15=0,"",INDEX(REGISTRO!B:B,$S15)) | C15: =IF($S15=0,"",INDEX(REGISTRO!H:H,$S15)) | E15: =IF($S15=0,"",INDEX(REGISTRO!M:M,$S15)) | S15: =IFERROR(MATCH($C$6&"|"&(COUNTIFS(REGISTRO!$C$3:$C$2002,$C$6,REGISTRO!$M$3:$M$2002,"<>")-2),REGISTRO!$O:$O,0),0) -> 0
B17: PROGRAMA DE MANTENIMIENTO (CAMBIOS) | M17: PROGRAMA DE INSPECCIÓN
B18: MANTENIMIENTO | C18: PROGRAMADO | D18: ÚLTIMA VEZ REALIZADO | E18: SISTEMA | F18: DESCRIPCIÓN | G18: CANTIDAD | H18: UNIDAD | I18: P. UNIT (S/) | J18: P. TOTAL (S/) | K18: TOTAL PM (S/) | M18: MANTENIMIENTO | N18: SISTEMA | O18: ACTIVIDAD | P18: TAREA
A19: =IFERROR(MATCH($C$9&"|1",BD_PLAN!$J:$J,0),0) -> 3 | B19: =IF($A19=0,"",IF(TRUE(),LEFT($R19,FIND(" ",$R19)-1),"")) -> PM1 | C19: =IF($A19=0,"",IF(TRUE(),INDEX(BD_CICLO!$E:$E,MATCH($C$9&"|"&$R19,BD_CICLO!$G:$G,0))&" "&$F$6,"")) -> 1000 KM | D19: =IF($A19=0,"",IF(TRUE(),IFERROR(1/(1/SUMPRODUCT(MAX((REGISTRO!$C$3:$C$2002=$C$6)*(REGISTRO!$H$3:$H$2002=$R19)*REGISTRO!$B$3:$B$2002))),""),"")) | E19: =IF($A19=0,"",IF(TRUE(),$S19,"")) -> MOTOR | F19: =IF($A19=0,"",INDEX(BD_PLAN!E:E,$A19)) -> ACEITE MOTOR 20W50 4T MINERAL | G19: =IF($A19=0,"",INDEX(BD_PLAN!F:F,$A19)) -> 1.5 | H19: =IF($A19=0,"",INDEX(BD_PLAN!G:G,$A19)) -> L | I19: =IF($A19=0,"",INDEX(BD_PLAN!H:H,$A19)) -> 20 | J19: =IF($A19=0,"",INDEX(BD_PLAN!I:I,$A19)) -> 30 | K19: =IF($A19=0,"",IF(TRUE(),SUMIFS(BD_PLAN!$I$3:$I$312,BD_PLAN!$B$3:$B$312,$C$9,BD_PLAN!$C$3:$C$312,$R19),"")) -> 55.25 | M19: =IF($Q19=0,"",IF(TRUE(),$T19,"")) -> PM1 - 1000 KM | N19: =IF($Q19=0,"",IF(TRUE(),$U19,"")) -> MOTOR | O19: =IF($Q19=0,"",INDEX(BD_INSPECCION!E:E,$Q19)) -> INSPECCIONAR | P19: =IF($Q19=0,"",INDEX(BD_INSPECCION!F:F,$Q19)) -> LUZ DE VÁLVULAS (REGULAR SI ES NECESARIO) | Q19: =IFERROR(MATCH($C$9&"|1",BD_INSPECCION!$G:$G,0),0) -> 3 | R19: =IF($A19=0,"",INDEX(BD_PLAN!C:C,$A19)) -> PM1 - 1000 KM | S19: =IF($A19=0,"",INDEX(BD_PLAN!D:D,$A19)) -> MOTOR | T19: =IF($Q19=0,"",INDEX(BD_INSPECCION!C:C,$Q19)) -> PM1 - 1000 KM | U19: =IF($Q19=0,"",INDEX(BD_INSPECCION!D:D,$Q19)) -> MOTOR
A20: =IFERROR(MATCH($C$9&"|2",BD_PLAN!$J:$J,0),0) -> 4 | B20: =IF($A20=0,"",IF($R20<>$R19,LEFT($R20,FIND(" ",$R20)-1),"")) | C20: =IF($A20=0,"",IF($R20<>$R19,INDEX(BD_CICLO!$E:$E,MATCH($C$9&"|"&$R20,BD_CICLO!$G:$G,0))&" "&$F$6,"")) | D20: =IF($A20=0,"",IF($R20<>$R19,IFERROR(1/(1/SUMPRODUCT(MAX((REGISTRO!$C$3:$C$2002=$C$6)*(REGISTRO!$H$3:$H$2002=$R20)*REGISTRO!$B$3:$B$2002))),""),"")) | E20: =IF($A20=0,"",IF(OR($R20<>$R19,$S20<>$S19),$S20,"")) | F20: =IF($A20=0,"",INDEX(BD_PLAN!E:E,$A20)) -> ARANDELA TAPÓN DE DRENAJE | G20: =IF($A20=0,"",INDEX(BD_PLAN!F:F,$A20)) -> 1 | H20: =IF($A20=0,"",INDEX(BD_PLAN!G:G,$A20)) -> UND. | I20: =IF($A20=0,"",INDEX(BD_PLAN!H:H,$A20)) -> 2 | J20: =IF($A20=0,"",INDEX(BD_PLAN!I:I,$A20)) -> 2 | K20: =IF($A20=0,"",IF($R20<>$R19,SUMIFS(BD_PLAN!$I$3:$I$312,BD_PLAN!$B$3:$B$312,$C$9,BD_PLAN!$C$3:$C$312,$R20),"")) | M20: =IF($Q20=0,"",IF($T20<>$T19,$T20,"")) | N20: =IF($Q20=0,"",IF(OR($T20<>$T19,$U20<>$U19),$U20,"")) | O20: =IF($Q20=0,"",INDEX(BD_INSPECCION!E:E,$Q20)) -> INSPECCIONAR | P20: =IF($Q20=0,"",INDEX(BD_INSPECCION!F:F,$Q20)) -> VELOCIDAD DE RALENTÍ | Q20: =IFERROR(MATCH($C$9&"|2",BD_INSPECCION!$G:$G,0),0) -> 4 | R20: =IF($A20=0,"",INDEX(BD_PLAN!C:C,$A20)) -> PM1 - 1000 KM | S20: =IF($A20=0,"",INDEX(BD_PLAN!D:D,$A20)) -> MOTOR | T20: =IF($Q20=0,"",INDEX(BD_INSPECCION!C:C,$Q20)) -> PM1 - 1000 KM | U20: =IF($Q20=0,"",INDEX(BD_INSPECCION!D:D,$Q20)) -> MOTOR
A21: =IFERROR(MATCH($C$9&"|3",BD_PLAN!$J:$J,0),0) -> 5 | B21: =IF($A21=0,"",IF($R21<>$R20,LEFT($R21,FIND(" ",$R21)-1),"")) | C21: =IF($A21=0,"",IF($R21<>$R20,INDEX(BD_CICLO!$E:$E,MATCH($C$9&"|"&$R21,BD_CICLO!$G:$G,0))&" "&$F$6,"")) | D21: =IF($A21=0,"",IF($R21<>$R20,IFERROR(1/(1/SUMPRODUCT(MAX((REGISTRO!$C$3:$C$2002=$C$6)*(REGISTRO!$H$3:$H$2002=$R21)*REGISTRO!$B$3:$B$2002))),""),"")) | E21: =IF($A21=0,"",IF(OR($R21<>$R20,$S21<>$S20),$S21,"")) -> CHASIS | F21: =IF($A21=0,"",INDEX(BD_PLAN!E:E,$A21)) -> GRASA MULTIPROPÓSITO | G21: =IF($A21=0,"",INDEX(BD_PLAN!F:F,$A21)) -> 0.5 | H21: =IF($A21=0,"",INDEX(BD_PLAN!G:G,$A21)) -> LBRS | I21: =IF($A21=0,"",INDEX(BD_PLAN!H:H,$A21)) -> 15 | J21: =IF($A21=0,"",INDEX(BD_PLAN!I:I,$A21)) -> 7.5 | K21: =IF($A21=0,"",IF($R21<>$R20,SUMIFS(BD_PLAN!$I$3:$I$312,BD_PLAN!$B$3:$B$312,$C$9,BD_PLAN!$C$3:$C$312,$R21),"")) | M21: =IF($Q21=0,"",IF($T21<>$T20,$T21,"")) | N21: =IF($Q21=0,"",IF(OR($T21<>$T20,$U21<>$U20),$U21,"")) | O21: =IF($Q21=0,"",INDEX(BD_INSPECCION!E:E,$Q21)) -> INSPECCIONAR | P21: =IF($Q21=0,"",INDEX(BD_INSPECCION!F:F,$Q21)) -> FUGAS DE ACEITE Y ESTADO DE EMPAQUES | Q21: =IFERROR(MATCH($C$9&"|3",BD_INSPECCION!$G:$G,0),0) -> 5 | R21: =IF($A21=0,"",INDEX(BD_PLAN!C:C,$A21)) -> PM1 - 1000 KM | S21: =IF($A21=0,"",INDEX(BD_PLAN!D:D,$A21)) -> CHASIS | T21: =IF($Q21=0,"",INDEX(BD_INSPECCION!C:C,$Q21)) -> PM1 - 1000 KM | U21: =IF($Q21=0,"",INDEX(BD_INSPECCION!D:D,$Q21)) -> MOTOR
A22: =IFERROR(MATCH($C$9&"|4",BD_PLAN!$J:$J,0),0) -> 6 | B22: =IF($A22=0,"",IF($R22<>$R21,LEFT($R22,FIND(" ",$R22)-1),"")) | C22: =IF($A22=0,"",IF($R22<>$R21,INDEX(BD_CICLO!$E:$E,MATCH($C$9&"|"&$R22,BD_CICLO!$G:$G,0))&" "&$F$6,"")) | D22: =IF($A22=0,"",IF($R22<>$R21,IFERROR(1/(1/SUMPRODUCT(MAX((REGISTRO!$C$3:$C$2002=$C$6)*(REGISTRO!$H$3:$H$2002=$R22)*REGISTRO!$B$3:$B$2002))),""),"")) | E22: =IF($A22=0,"",IF(OR($R22<>$R21,$S22<>$S21),$S22,"")) -> SERVICIO GENERAL | F22: =IF($A22=0,"",INDEX(BD_PLAN!E:E,$A22)) -> TRAPO INDUSTRIAL | G22: =IF($A22=0,"",INDEX(BD_PLAN!F:F,$A22)) -> 0.5 | H22: =IF($A22=0,"",INDEX(BD_PLAN!G:G,$A22)) -> KG | I22: =IF($A22=0,"",INDEX(BD_PLAN!H:H,$A22)) -> 4.5 | J22: =IF($A22=0,"",INDEX(BD_PLAN!I:I,$A22)) -> 2.25 | K22: =IF($A22=0,"",IF($R22<>$R21,SUMIFS(BD_PLAN!$I$3:$I$312,BD_PLAN!$B$3:$B$312,$C$9,BD_PLAN!$C$3:$C$312,$R22),"")) | M22: =IF($Q22=0,"",IF($T22<>$T21,$T22,"")) | N22: =IF($Q22=0,"",IF(OR($T22<>$T21,$U22<>$U21),$U22,"")) | O22: =IF($Q22=0,"",INDEX(BD_INSPECCION!E:E,$Q22)) -> LIMPIAR | P22: =IF($Q22=0,"",INDEX(BD_INSPECCION!F:F,$Q22)) -> MALLA (COLADOR) DE ACEITE | Q22: =IFERROR(MATCH($C$9&"|4",BD_INSPECCION!$G:$G,0),0) -> 6 | R22: =IF($A22=0,"",INDEX(BD_PLAN!C:C,$A22)) -> PM1 - 1000 KM | S22: =IF($A22=0,"",INDEX(BD_PLAN!D:D,$A22)) -> SERVICIO GENERAL | T22: =IF($Q22=0,"",INDEX(BD_INSPECCION!C:C,$Q22)) -> PM1 - 1000 KM | U22: =IF($Q22=0,"",INDEX(BD_INSPECCION!D:D,$Q22)) -> MOTOR
A23: =IFERROR(MATCH($C$9&"|5",BD_PLAN!$J:$J,0),0) -> 7 | B23: =IF($A23=0,"",IF($R23<>$R22,LEFT($R23,FIND(" ",$R23)-1),"")) | C23: =IF($A23=0,"",IF($R23<>$R22,INDEX(BD_CICLO!$E:$E,MATCH($C$9&"|"&$R23,BD_CICLO!$G:$G,0))&" "&$F$6,"")) | D23: =IF($A23=0,"",IF($R23<>$R22,IFERROR(1/(1/SUMPRODUCT(MAX((REGISTRO!$C$3:$C$2002=$C$6)*(REGISTRO!$H$3:$H$2002=$R23)*REGISTRO!$B$3:$B$2002))),""),"")) | E23: =IF($A23=0,"",IF(OR($R23<>$R22,$S23<>$S22),$S23,"")) | F23: =IF($A23=0,"",INDEX(BD_PLAN!E:E,$A23)) -> GASOLINA 90 OCT | G23: =IF($A23=0,"",INDEX(BD_PLAN!F:F,$A23)) -> 0.25 | H23: =IF($A23=0,"",INDEX(BD_PLAN!G:G,$A23)) -> GL | I23: =IF($A23=0,"",INDEX(BD_PLAN!H:H,$A23)) -> 24 | J23: =IF($A23=0,"",INDEX(BD_PLAN!I:I,$A23)) -> 6 | K23: =IF($A23=0,"",IF($R23<>$R22,SUMIFS(BD_PLAN!$I$3:$I$312,BD_PLAN!$B$3:$B$312,$C$9,BD_PLAN!$C$3:$C$312,$R23),"")) | M23: =IF($Q23=0,"",IF($T23<>$T22,$T23,"")) | N23: =IF($Q23=0,"",IF(OR($T23<>$T22,$U23<>$U22),$U23,"")) -> ADMISIÓN DE AIRE | O23: =IF($Q23=0,"",INDEX(BD_INSPECCION!E:E,$Q23)) -> LIMPIAR | P23: =IF($Q23=0,"",INDEX(BD_INSPECCION!F:F,$Q23)) -> FILTRO DE AIRE | Q23: =IFERROR(MATCH($C$9&"|5",BD_INSPECCION!$G:$G,0),0) -> 7 | R23: =IF($A23=0,"",INDEX(BD_PLAN!C:C,$A23)) -> PM1 - 1000 KM | S23: =IF($A23=0,"",INDEX(BD_PLAN!D:D,$A23)) -> SERVICIO GENERAL | T23: =IF($Q23=0,"",INDEX(BD_INSPECCION!C:C,$Q23)) -> PM1 - 1000 KM | U23: =IF($Q23=0,"",INDEX(BD_INSPECCION!D:D,$Q23)) -> ADMISIÓN DE AIRE
A24: =IFERROR(MATCH($C$9&"|6",BD_PLAN!$J:$J,0),0) -> 8 | B24: =IF($A24=0,"",IF($R24<>$R23,LEFT($R24,FIND(" ",$R24)-1),"")) | C24: =IF($A24=0,"",IF($R24<>$R23,INDEX(BD_CICLO!$E:$E,MATCH($C$9&"|"&$R24,BD_CICLO!$G:$G,0))&" "&$F$6,"")) | D24: =IF($A24=0,"",IF($R24<>$R23,IFERROR(1/(1/SUMPRODUCT(MAX((REGISTRO!$C$3:$C$2002=$C$6)*(REGISTRO!$H$3:$H$2002=$R24)*REGISTRO!$B$3:$B$2002))),""),"")) | E24: =IF($A24=0,"",IF(OR($R24<>$R23,$S24<>$S23),$S24,"")) -> COMBUSTIBLE | F24: =IF($A24=0,"",INDEX(BD_PLAN!E:E,$A24)) -> LIMPIA CARBURADOR | G24: =IF($A24=0,"",INDEX(BD_PLAN!F:F,$A24)) -> 0.5 | H24: =IF($A24=0,"",INDEX(BD_PLAN!G:G,$A24)) -> UND. | I24: =IF($A24=0,"",INDEX(BD_PLAN!H:H,$A24)) -> 15 | J24: =IF($A24=0,"",INDEX(BD_PLAN!I:I,$A24)) -> 7.5 | K24: =IF($A24=0,"",IF($R24<>$R23,SUMIFS(BD_PLAN!$I$3:$I$312,BD_PLAN!$B$3:$B$312,$C$9,BD_PLAN!$C$3:$C$312,$R24),"")) | M24: =IF($Q24=0,"",IF($T24<>$T23,$T24,"")) | N24: =IF($Q24=0,"",IF(OR($T24<>$T23,$U24<>$U23),$U24,"")) -> COMBUSTIBLE | O24: =IF($Q24=0,"",INDEX(BD_INSPECCION!E:E,$Q24)) -> INSPECCIONAR | P24: =IF($Q24=0,"",INDEX(BD_INSPECCION!F:F,$Q24)) -> MANGUERA DE COMBUSTIBLE (GRIETAS Y FUGAS) | Q24: =IFERROR(MATCH($C$9&"|6",BD_INSPECCION!$G:$G,0),0) -> 8 | R24: =IF($A24=0,"",INDEX(BD_PLAN!C:C,$A24)) -> PM1 - 1000 KM | S24: =IF($A24=0,"",INDEX(BD_PLAN!D:D,$A24)) -> COMBUSTIBLE | T24: =IF($Q24=0,"",INDEX(BD_INSPECCION!C:C,$Q24)) -> PM1 - 1000 KM | U24: =IF($Q24=0,"",INDEX(BD_INSPECCION!D:D,$Q24)) -> COMBUSTIBLE
A25: =IFERROR(MATCH($C$9&"|7",BD_PLAN!$J:$J,0),0) -> 9 | B25: =IF($A25=0,"",IF($R25<>$R24,LEFT($R25,FIND(" ",$R25)-1),"")) -> PM2 | C25: =IF($A25=0,"",IF($R25<>$R24,INDEX(BD_CICLO!$E:$E,MATCH($C$9&"|"&$R25,BD_CICLO!$G:$G,0))&" "&$F$6,"")) -> 2000 KM | D25: =IF($A25=0,"",IF($R25<>$R24,IFERROR(1/(1/SUMPRODUCT(MAX((REGISTRO!$C$3:$C$2002=$C$6)*(REGISTRO!$H$3:$H$2002=$R25)*REGISTRO!$B$3:$B$2002))),""),"")) | E25: =IF($A25=0,"",IF(OR($R25<>$R24,$S25<>$S24),$S25,"")) -> MOTOR | F25: =IF($A25=0,"",INDEX(BD_PLAN!E:E,$A25)) -> ACEITE MOTOR 20W50 4T MINERAL | G25: =IF($A25=0,"",INDEX(BD_PLAN!F:F,$A25)) -> 1.5 | H25: =IF($A25=0,"",INDEX(BD_PLAN!G:G,$A25)) -> L | I25: =IF($A25=0,"",INDEX(BD_PLAN!H:H,$A25)) -> 20 | J25: =IF($A25=0,"",INDEX(BD_PLAN!I:I,$A25)) -> 30 | K25: =IF($A25=0,"",IF($R25<>$R24,SUMIFS(BD_PLAN!$I$3:$I$312,BD_PLAN!$B$3:$B$312,$C$9,BD_PLAN!$C$3:$C$312,$R25),"")) -> 63.25 | M25: =IF($Q25=0,"",IF($T25<>$T24,$T25,"")) | N25: =IF($Q25=0,"",IF(OR($T25<>$T24,$U25<>$U24),$U25,"")) | O25: =IF($Q25=0,"",INDEX(BD_INSPECCION!E:E,$Q25)) -> INSPECCIONAR | P25: =IF($Q25=0,"",INDEX(BD_INSPECCION!F:F,$Q25)) -> FUNCIONAMIENTO DEL ACELERADOR Y CHOKE | Q25: =IFERROR(MATCH($C$9&"|7",BD_INSPECCION!$G:$G,0),0) -> 9 | R25: =IF($A25=0,"",INDEX(BD_PLAN!C:C,$A25)) -> PM2 - 2000 KM | S25: =IF($A25=0,"",INDEX(BD_PLAN!D:D,$A25)) -> MOTOR | T25: =IF($Q25=0,"",INDEX(BD_INSPECCION!C:C,$Q25)) -> PM1 - 1000 KM | U25: =IF($Q25=0,"",INDEX(BD_INSPECCION!D:D,$Q25)) -> COMBUSTIBLE
A26: =IFERROR(MATCH($C$9&"|8",BD_PLAN!$J:$J,0),0) -> 10 | B26: =IF($A26=0,"",IF($R26<>$R25,LEFT($R26,FIND(" ",$R26)-1),"")) | C26: =IF($A26=0,"",IF($R26<>$R25,INDEX(BD_CICLO!$E:$E,MATCH($C$9&"|"&$R26,BD_CICLO!$G:$G,0))&" "&$F$6,"")) | D26: =IF($A26=0,"",IF($R26<>$R25,IFERROR(1/(1/SUMPRODUCT(MAX((REGISTRO!$C$3:$C$2002=$C$6)*(REGISTRO!$H$3:$H$2002=$R26)*REGISTRO!$B$3:$B$2002))),""),"")) | E26: =IF($A26=0,"",IF(OR($R26<>$R25,$S26<>$S25),$S26,"")) | F26: =IF($A26=0,"",INDEX(BD_PLAN!E:E,$A26)) -> ARANDELA TAPÓN DE DRENAJE | G26: =IF($A26=0,"",INDEX(BD_PLAN!F:F,$A26)) -> 1 | H26: =IF($A26=0,"",INDEX(BD_PLAN!G:G,$A26)) -> UND. | I26: =IF($A26=0,"",INDEX(BD_PLAN!H:H,$A26)) -> 2 | J26: =IF($A26=0,"",INDEX(BD_PLAN!I:I,$A26)) -> 2 | K26: =IF($A26=0,"",IF($R26<>$R25,SUMIFS(BD_PLAN!$I$3:$I$312,BD_PLAN!$B$3:$B$312,$C$9,BD_PLAN!$C$3:$C$312,$R26),"")) | M26: =IF($Q26=0,"",IF($T26<>$T25,$T26,"")) | N26: =IF($Q26=0,"",IF(OR($T26<>$T25,$U26<>$U25),$U26,"")) -> ENCENDIDO | O26: =IF($Q26=0,"",INDEX(BD_INSPECCION!E:E,$Q26)) -> INSPECCIONAR | P26: =IF($Q26=0,"",INDEX(BD_INSPECCION!F:F,$Q26)) -> BUJÍA: LIMPIAR Y CALIBRAR | Q26: =IFERROR(MATCH($C$9&"|8",BD_INSPECCION!$G:$G,0),0) -> 10 | R26: =IF($A26=0,"",INDEX(BD_PLAN!C:C,$A26)) -> PM2 - 2000 KM | S26: =IF($A26=0,"",INDEX(BD_PLAN!D:D,$A26)) -> MOTOR | T26: =IF($Q26=0,"",INDEX(BD_INSPECCION!C:C,$Q26)) -> PM1 - 1000 KM | U26: =IF($Q26=0,"",INDEX(BD_INSPECCION!D:D,$Q26)) -> ENCENDIDO
A27: =IFERROR(MATCH($C$9&"|9",BD_PLAN!$J:$J,0),0) -> 11 | B27: =IF($A27=0,"",IF($R27<>$R26,LEFT($R27,FIND(" ",$R27)-1),"")) | C27: =IF($A27=0,"",IF($R27<>$R26,INDEX(BD_CICLO!$E:$E,MATCH($C$9&"|"&$R27,BD_CICLO!$G:$G,0))&" "&$F$6,"")) | D27: =IF($A27=0,"",IF($R27<>$R26,IFERROR(1/(1/SUMPRODUCT(MAX((REGISTRO!$C$3:$C$2002=$C$6)*(REGISTRO!$H$3:$H$2002=$R27)*REGISTRO!$B$3:$B$2002))),""),"")) | E27: =IF($A27=0,"",IF(OR($R27<>$R26,$S27<>$S26),$S27,"")) -> COMBUSTIBLE | F27: =IF($A27=0,"",INDEX(BD_PLAN!E:E,$A27)) -> FILTRO DE GASOLINA EN LÍNEA | G27: =IF($A27=0,"",INDEX(BD_PLAN!F:F,$A27)) -> 1 | H27: =IF($A27=0,"",INDEX(BD_PLAN!G:G,$A27)) -> UND. | I27: =IF($A27=0,"",INDEX(BD_PLAN!H:H,$A27)) -> 8 | J27: =IF($A27=0,"",INDEX(BD_PLAN!I:I,$A27)) -> 8 | K27: =IF($A27=0,"",IF($R27<>$R26,SUMIFS(BD_PLAN!$I$3:$I$312,BD_PLAN!$B$3:$B$312,$C$9,BD_PLAN!$C$3:$C$312,$R27),"")) | M27: =IF($Q27=0,"",IF($T27<>$T26,$T27,"")) | N27: =IF($Q27=0,"",IF(OR($T27<>$T26,$U27<>$U26),$U27,"")) -> TRANSMISIÓN | O27: =IF($Q27=0,"",INDEX(BD_INSPECCION!E:E,$Q27)) -> INSPECCIONAR | P27: =IF($Q27=0,"",INDEX(BD_INSPECCION!F:F,$Q27)) -> EMBRAGUE (JUEGO LIBRE DEL CABLE) Y CAMBIOS | Q27: =IFERROR(MATCH($C$9&"|9",BD_INSPECCION!$G:$G,0),0) -> 11 | R27: =IF($A27=0,"",INDEX(BD_PLAN!C:C,$A27)) -> PM2 - 2000 KM | S27: =IF($A27=0,"",INDEX(BD_PLAN!D:D,$A27)) -> COMBUSTIBLE | T27: =IF($Q27=0,"",INDEX(BD_INSPECCION!C:C,$Q27)) -> PM1 - 1000 KM | U27: =IF($Q27=0,"",INDEX(BD_INSPECCION!D:D,$Q27)) -> TRANSMISIÓN
A28: =IFERROR(MATCH($C$9&"|10",BD_PLAN!$J:$J,0),0) -> 12 | B28: =IF($A28=0,"",IF($R28<>$R27,LEFT($R28,FIND(" ",$R28)-1),"")) | C28: =IF($A28=0,"",IF($R28<>$R27,INDEX(BD_CICLO!$E:$E,MATCH($C$9&"|"&$R28,BD_CICLO!$G:$G,0))&" "&$F$6,"")) | D28: =IF($A28=0,"",IF($R28<>$R27,IFERROR(1/(1/SUMPRODUCT(MAX((REGISTRO!$C$3:$C$2002=$C$6)*(REGISTRO!$H$3:$H$2002=$R28)*REGISTRO!$B$3:$B$2002))),""),"")) | E28: =IF($A28=0,"",IF(OR($R28<>$R27,$S28<>$S27),$S28,"")) | F28: =IF($A28=0,"",INDEX(BD_PLAN!E:E,$A28)) -> LIMPIA CARBURADOR | G28: =IF($A28=0,"",INDEX(BD_PLAN!F:F,$A28)) -> 0.5 | H28: =IF($A28=0,"",INDEX(BD_PLAN!G:G,$A28)) -> UND. | I28: =IF($A28=0,"",INDEX(BD_PLAN!H:H,$A28)) -> 15 | J28: =IF($A28=0,"",INDEX(BD_PLAN!I:I,$A28)) -> 7.5 | K28: =IF($A28=0,"",IF($R28<>$R27,SUMIFS(BD_PLAN!$I$3:$I$312,BD_PLAN!$B$3:$B$312,$C$9,BD_PLAN!$C$3:$C$312,$R28),"")) | M28: =IF($Q28=0,"",IF($T28<>$T27,$T28,"")) | N28: =IF($Q28=0,"",IF(OR($T28<>$T27,$U28<>$U27),$U28,"")) -> CARDÁN | O28: =IF($Q28=0,"",INDEX(BD_INSPECCION!E:E,$Q28)) -> INSPECCIONAR | P28: =IF($Q28=0,"",INDEX(BD_INSPECCION!F:F,$Q28)) -> CRUCETAS (JUEGO) Y GUARDAPOLVOS | Q28: =IFERROR(MATCH($C$9&"|10",BD_INSPECCION!$G:$G,0),0) -> 12 | R28: =IF($A28=0,"",INDEX(BD_PLAN!C:C,$A28)) -> PM2 - 2000 KM | S28: =IF($A28=0,"",INDEX(BD_PLAN!D:D,$A28)) -> COMBUSTIBLE | T28: =IF($Q28=0,"",INDEX(BD_INSPECCION!C:C,$Q28)) -> PM1 - 1000 KM | U28: =IF($Q28=0,"",INDEX(BD_INSPECCION!D:D,$Q28)) -> CARDÁN
A29: =IFERROR(MATCH($C$9&"|11",BD_PLAN!$J:$J,0),0) -> 13 | B29: =IF($A29=0,"",IF($R29<>$R28,LEFT($R29,FIND(" ",$R29)-1),"")) | C29: =IF($A29=0,"",IF($R29<>$R28,INDEX(BD_CICLO!$E:$E,MATCH($C$9&"|"&$R29,BD_CICLO!$G:$G,0))&" "&$F$6,"")) | D29: =IF($A29=0,"",IF($R29<>$R28,IFERROR(1/(1/SUMPRODUCT(MAX((REGISTRO!$C$3:$C$2002=$C$6)*(REGISTRO!$H$3:$H$2002=$R29)*REGISTRO!$B$3:$B$2002))),""),"")) | E29: =IF($A29=0,"",IF(OR($R29<>$R28,$S29<>$S28),$S29,"")) -> CHASIS | F29: =IF($A29=0,"",INDEX(BD_PLAN!E:E,$A29)) -> GRASA MULTIPROPÓSITO | G29: =IF($A29=0,"",INDEX(BD_PLAN!F:F,$A29)) -> 0.5 | H29: =IF($A29=0,"",INDEX(BD_PLAN!G:G,$A29)) -> LBRS | I29: =IF($A29=0,"",INDEX(BD_PLAN!H:H,$A29)) -> 15 | J29: =IF($A29=0,"",INDEX(BD_PLAN!I:I,$A29)) -> 7.5 | K29: =IF($A29=0,"",IF($R29<>$R28,SUMIFS(BD_PLAN!$I$3:$I$312,BD_PLAN!$B$3:$B$312,$C$9,BD_PLAN!$C$3:$C$312,$R29),"")) | M29: =IF($Q29=0,"",IF($T29<>$T28,$T29,"")) | N29: =IF($Q29=0,"",IF(OR($T29<>$T28,$U29<>$U28),$U29,"")) | O29: =IF($Q29=0,"",INDEX(BD_INSPECCION!E:E,$Q29)) -> LUBRICAR | P29: =IF($Q29=0,"",INDEX(BD_INSPECCION!F:F,$Q29)) -> CRUCETAS Y ESTRIADO DEL CARDÁN | Q29: =IFERROR(MATCH($C$9&"|11",BD_INSPECCION!$G:$G,0),0) -> 13 | R29: =IF($A29=0,"",INDEX(BD_PLAN!C:C,$A29)) -> PM2 - 2000 KM | S29: =IF($A29=0,"",INDEX(BD_PLAN!D:D,$A29)) -> CHASIS | T29: =IF($Q29=0,"",INDEX(BD_INSPECCION!C:C,$Q29)) -> PM1 - 1000 KM | U29: =IF($Q29=0,"",INDEX(BD_INSPECCION!D:D,$Q29)) -> CARDÁN
A30: =IFERROR(MATCH($C$9&"|12",BD_PLAN!$J:$J,0),0) -> 14 | B30: =IF($A30=0,"",IF($R30<>$R29,LEFT($R30,FIND(" ",$R30)-1),"")) | C30: =IF($A30=0,"",IF($R30<>$R29,INDEX(BD_CICLO!$E:$E,MATCH($C$9&"|"&$R30,BD_CICLO!$G:$G,0))&" "&$F$6,"")) | D30: =IF($A30=0,"",IF($R30<>$R29,IFERROR(1/(1/SUMPRODUCT(MAX((REGISTRO!$C$3:$C$2002=$C$6)*(REGISTRO!$H$3:$H$2002=$R30)*REGISTRO!$B$3:$B$2002))),""),"")) | E30: =IF($A30=0,"",IF(OR($R30<>$R29,$S30<>$S29),$S30,"")) -> SERVICIO GENERAL | F30: =IF($A30=0,"",INDEX(BD_PLAN!E:E,$A30)) -> TRAPO INDUSTRIAL | G30: =IF($A30=0,"",INDEX(BD_PLAN!F:F,$A30)) -> 0.5 | H30: =IF($A30=0,"",INDEX(BD_PLAN!G:G,$A30)) -> KG | I30: =IF($A30=0,"",INDEX(BD_PLAN!H:H,$A30)) -> 4.5 | J30: =IF($A30=0,"",INDEX(BD_PLAN!I:I,$A30)) -> 2.25 | K30: =IF($A30=0,"",IF($R30<>$R29,SUMIFS(BD_PLAN!$I$3:$I$312,BD_PLAN!$B$3:$B$312,$C$9,BD_PLAN!$C$3:$C$312,$R30),"")) | M30: =IF($Q30=0,"",IF($T30<>$T29,$T30,"")) | N30: =IF($Q30=0,"",IF(OR($T30<>$T29,$U30<>$U29),$U30,"")) -> DIFERENCIAL | O30: =IF($Q30=0,"",INDEX(BD_INSPECCION!E:E,$Q30)) -> INSPECCIONAR | P30: =IF($Q30=0,"",INDEX(BD_INSPECCION!F:F,$Q30)) -> NIVEL DE ACEITE Y FUGAS | Q30: =IFERROR(MATCH($C$9&"|12",BD_INSPECCION!$G:$G,0),0) -> 14 | R30: =IF($A30=0,"",INDEX(BD_PLAN!C:C,$A30)) -> PM2 - 2000 KM | S30: =IF($A30=0,"",INDEX(BD_PLAN!D:D,$A30)) -> SERVICIO GENERAL | T30: =IF($Q30=0,"",INDEX(BD_INSPECCION!C:C,$Q30)) -> PM1 - 1000 KM | U30: =IF($Q30=0,"",INDEX(BD_INSPECCION!D:D,$Q30)) -> DIFERENCIAL
A31: =IFERROR(MATCH($C$9&"|13",BD_PLAN!$J:$J,0),0) -> 15 | B31: =IF($A31=0,"",IF($R31<>$R30,LEFT($R31,FIND(" ",$R31)-1),"")) | C31: =IF($A31=0,"",IF($R31<>$R30,INDEX(BD_CICLO!$E:$E,MATCH($C$9&"|"&$R31,BD_CICLO!$G:$G,0))&" "&$F$6,"")) | D31: =IF($A31=0,"",IF($R31<>$R30,IFERROR(1/(1/SUMPRODUCT(MAX((REGISTRO!$C$3:$C$2002=$C$6)*(REGISTRO!$H$3:$H$2002=$R31)*REGISTRO!$B$3:$B$2002))),""),"")) | E31: =IF($A31=0,"",IF(OR($R31<>$R30,$S31<>$S30),$S31,"")) | F31: =IF($A31=0,"",INDEX(BD_PLAN!E:E,$A31)) -> GASOLINA 90 OCT | G31: =IF($A31=0,"",INDEX(BD_PLAN!F:F,$A31)) -> 0.25 | H31: =IF($A31=0,"",INDEX(BD_PLAN!G:G,$A31)) -> GL | I31: =IF($A31=0,"",INDEX(BD_PLAN!H:H,$A31)) -> 24 | J31: =IF($A31=0,"",INDEX(BD_PLAN!I:I,$A31)) -> 6 | K31: =IF($A31=0,"",IF($R31<>$R30,SUMIFS(BD_PLAN!$I$3:$I$312,BD_PLAN!$B$3:$B$312,$C$9,BD_PLAN!$C$3:$C$312,$R31),"")) | M31: =IF($Q31=0,"",IF($T31<>$T30,$T31,"")) | N31: =IF($Q31=0,"",IF(OR($T31<>$T30,$U31<>$U30),$U31,"")) | O31: =IF($Q31=0,"",INDEX(BD_INSPECCION!E:E,$Q31)) -> INSPECCIONAR | P31: =IF($Q31=0,"",INDEX(BD_INSPECCION!F:F,$Q31)) -> RUIDOS Y RESPIRADERO | Q31: =IFERROR(MATCH($C$9&"|13",BD_INSPECCION!$G:$G,0),0) -> 15 | R31: =IF($A31=0,"",INDEX(BD_PLAN!C:C,$A31)) -> PM2 - 2000 KM | S31: =IF($A31=0,"",INDEX(BD_PLAN!D:D,$A31)) -> SERVICIO GENERAL | T31: =IF($Q31=0,"",INDEX(BD_INSPECCION!C:C,$Q31)) -> PM1 - 1000 KM | U31: =IF($Q31=0,"",INDEX(BD_INSPECCION!D:D,$Q31)) -> DIFERENCIAL
A32: =IFERROR(MATCH($C$9&"|14",BD_PLAN!$J:$J,0),0) -> 16 | B32: =IF($A32=0,"",IF($R32<>$R31,LEFT($R32,FIND(" ",$R32)-1),"")) -> PM3 | C32: =IF($A32=0,"",IF($R32<>$R31,INDEX(BD_CICLO!$E:$E,MATCH($C$9&"|"&$R32,BD_CICLO!$G:$G,0))&" "&$F$6,"")) -> 3000 KM | D32: =IF($A32=0,"",IF($R32<>$R31,IFERROR(1/(1/SUMPRODUCT(MAX((REGISTRO!$C$3:$C$2002=$C$6)*(REGISTRO!$H$3:$H$2002=$R32)*REGISTRO!$B$3:$B$2002))),""),"")) | E32: =IF($A32=0,"",IF(OR($R32<>$R31,$S32<>$S31),$S32,"")) -> MOTOR | F32: =IF($A32=0,"",INDEX(BD_PLAN!E:E,$A32)) -> ACEITE MOTOR 20W50 4T MINERAL | G32: =IF($A32=0,"",INDEX(BD_PLAN!F:F,$A32)) -> 1.5 | H32: =IF($A32=0,"",INDEX(BD_PLAN!G:G,$A32)) -> L | I32: =IF($A32=0,"",INDEX(BD_PLAN!H:H,$A32)) -> 20 | J32: =IF($A32=0,"",INDEX(BD_PLAN!I:I,$A32)) -> 30 | K32: =IF($A32=0,"",IF($R32<>$R31,SUMIFS(BD_PLAN!$I$3:$I$312,BD_PLAN!$B$3:$B$312,$C$9,BD_PLAN!$C$3:$C$312,$R32),"")) -> 55.25 | M32: =IF($Q32=0,"",IF($T32<>$T31,$T32,"")) | N32: =IF($Q32=0,"",IF(OR($T32<>$T31,$U32<>$U31),$U32,"")) -> EJES / RODAJES | O32: =IF($Q32=0,"",INDEX(BD_INSPECCION!E:E,$Q32)) -> INSPECCIONAR | P32: =IF($Q32=0,"",INDEX(BD_INSPECCION!F:F,$Q32)) -> PALIERES, RODAJES DE RUEDA Y RETENES (JUEGO, RUIDO Y FUGAS) | Q32: =IFERROR(MATCH($C$9&"|14",BD_INSPECCION!$G:$G,0),0) -> 16 | R32: =IF($A32=0,"",INDEX(BD_PLAN!C:C,$A32)) -> PM3 - 3000 KM | S32: =IF($A32=0,"",INDEX(BD_PLAN!D:D,$A32)) -> MOTOR | T32: =IF($Q32=0,"",INDEX(BD_INSPECCION!C:C,$Q32)) -> PM1 - 1000 KM | U32: =IF($Q32=0,"",INDEX(BD_INSPECCION!D:D,$Q32)) -> EJES / RODAJES
A33: =IFERROR(MATCH($C$9&"|15",BD_PLAN!$J:$J,0),0) -> 17 | B33: =IF($A33=0,"",IF($R33<>$R32,LEFT($R33,FIND(" ",$R33)-1),"")) | C33: =IF($A33=0,"",IF($R33<>$R32,INDEX(BD_CICLO!$E:$E,MATCH($C$9&"|"&$R33,BD_CICLO!$G:$G,0))&" "&$F$6,"")) | D33: =IF($A33=0,"",IF($R33<>$R32,IFERROR(1/(1/SUMPRODUCT(MAX((REGISTRO!$C$3:$C$2002=$C$6)*(REGISTRO!$H$3:$H$2002=$R33)*REGISTRO!$B$3:$B$2002))),""),"")) | E33: =IF($A33=0,"",IF(OR($R33<>$R32,$S33<>$S32),$S33,"")) | F33: =IF($A33=0,"",INDEX(BD_PLAN!E:E,$A33)) -> ARANDELA TAPÓN DE DRENAJE | G33: =IF($A33=0,"",INDEX(BD_PLAN!F:F,$A33)) -> 1 | H33: =IF($A33=0,"",INDEX(BD_PLAN!G:G,$A33)) -> UND. | I33: =IF($A33=0,"",INDEX(BD_PLAN!H:H,$A33)) -> 2 | J33: =IF($A33=0,"",INDEX(BD_PLAN!I:I,$A33)) -> 2 | K33: =IF($A33=0,"",IF($R33<>$R32,SUMIFS(BD_PLAN!$I$3:$I$312,BD_PLAN!$B$3:$B$312,$C$9,BD_PLAN!$C$3:$C$312,$R33),"")) | M33: =IF($Q33=0,"",IF($T33<>$T32,$T33,"")) | N33: =IF($Q33=0,"",IF(OR($T33<>$T32,$U33<>$U32),$U33,"")) -> FRENOS | O33: =IF($Q33=0,"",INDEX(BD_INSPECCION!E:E,$Q33)) -> INSPECCIONAR | P33: =IF($Q33=0,"",INDEX(BD_INSPECCION!F:F,$Q33)) -> ZAPATAS, TAMBORES, CABLES Y JUEGO LIBRE DE PALANCA Y PEDAL | Q33: =IFERROR(MATCH($C$9&"|15",BD_INSPECCION!$G:$G,0),0) -> 17 | R33: =IF($A33=0,"",INDEX(BD_PLAN!C:C,$A33)) -> PM3 - 3000 KM | S33: =IF($A33=0,"",INDEX(BD_PLAN!D:D,$A33)) -> MOTOR | T33: =IF($Q33=0,"",INDEX(BD_INSPECCION!C:C,$Q33)) -> PM1 - 1000 KM | U33: =IF($Q33=0,"",INDEX(BD_INSPECCION!D:D,$Q33)) -> FRENOS
A34: =IFERROR(MATCH($C$9&"|16",BD_PLAN!$J:$J,0),0) -> 18 | B34: =IF($A34=0,"",IF($R34<>$R33,LEFT($R34,FIND(" ",$R34)-1),"")) | C34: =IF($A34=0,"",IF($R34<>$R33,INDEX(BD_CICLO!$E:$E,MATCH($C$9&"|"&$R34,BD_CICLO!$G:$G,0))&" "&$F$6,"")) | D34: =IF($A34=0,"",IF($R34<>$R33,IFERROR(1/(1/SUMPRODUCT(MAX((REGISTRO!$C$3:$C$2002=$C$6)*(REGISTRO!$H$3:$H$2002=$R34)*REGISTRO!$B$3:$B$2002))),""),"")) | E34: =IF($A34=0,"",IF(OR($R34<>$R33,$S34<>$S33),$S34,"")) -> CHASIS | F34: =IF($A34=0,"",INDEX(BD_PLAN!E:E,$A34)) -> GRASA MULTIPROPÓSITO | G34: =IF($A34=0,"",INDEX(BD_PLAN!F:F,$A34)) -> 0.5 | H34: =IF($A34=0,"",INDEX(BD_PLAN!G:G,$A34)) -> LBRS | I34: =IF($A34=0,"",INDEX(BD_PLAN!H:H,$A34)) -> 15 | J34: =IF($A34=0,"",INDEX(BD_PLAN!I:I,$A34)) -> 7.5 | K34: =IF($A34=0,"",IF($R34<>$R33,SUMIFS(BD_PLAN!$I$3:$I$312,BD_PLAN!$B$3:$B$312,$C$9,BD_PLAN!$C$3:$C$312,$R34),"")) | M34: =IF($Q34=0,"",IF($T34<>$T33,$T34,"")) | N34: =IF($Q34=0,"",IF(OR($T34<>$T33,$U34<>$U33),$U34,"")) -> DIRECCIÓN | O34: =IF($Q34=0,"",INDEX(BD_INSPECCION!E:E,$Q34)) -> INSPECCIONAR | P34: =IF($Q34=0,"",INDEX(BD_INSPECCION!F:F,$Q34)) -> RODAJES DE DIRECCIÓN Y JUEGO DEL TIMÓN | Q34: =IFERROR(MATCH($C$9&"|16",BD_INSPECCION!$G:$G,0),0) -> 18 | R34: =IF($A34=0,"",INDEX(BD_PLAN!C:C,$A34)) -> PM3 - 3000 KM | S34: =IF($A34=0,"",INDEX(BD_PLAN!D:D,$A34)) -> CHASIS | T34: =IF($Q34=0,"",INDEX(BD_INSPECCION!C:C,$Q34)) -> PM1 - 1000 KM | U34: =IF($Q34=0,"",INDEX(BD_INSPECCION!D:D,$Q34)) -> DIRECCIÓN
A35: =IFERROR(MATCH($C$9&"|17",BD_PLAN!$J:$J,0),0) -> 19 | B35: =IF($A35=0,"",IF($R35<>$R34,LEFT($R35,FIND(" ",$R35)-1),"")) | C35: =IF($A35=0,"",IF($R35<>$R34,INDEX(BD_CICLO!$E:$E,MATCH($C$9&"|"&$R35,BD_CICLO!$G:$G,0))&" "&$F$6,"")) | D35: =IF($A35=0,"",IF($R35<>$R34,IFERROR(1/(1/SUMPRODUCT(MAX((REGISTRO!$C$3:$C$2002=$C$6)*(REGISTRO!$H$3:$H$2002=$R35)*REGISTRO!$B$3:$B$2002))),""),"")) | E35: =IF($A35=0,"",IF(OR($R35<>$R34,$S35<>$S34),$S35,"")) -> SERVICIO GENERAL | F35: =IF($A35=0,"",INDEX(BD_PLAN!E:E,$A35)) -> TRAPO INDUSTRIAL | G35: =IF($A35=0,"",INDEX(BD_PLAN!F:F,$A35)) -> 0.5 | H35: =IF($A35=0,"",INDEX(BD_PLAN!G:G,$A35)) -> KG | I35: =IF($A35=0,"",INDEX(BD_PLAN!H:H,$A35)) -> 4.5 | J35: =IF($A35=0,"",INDEX(BD_PLAN!I:I,$A35)) -> 2.25 | K35: =IF($A35=0,"",IF($R35<>$R34,SUMIFS(BD_PLAN!$I$3:$I$312,BD_PLAN!$B$3:$B$312,$C$9,BD_PLAN!$C$3:$C$312,$R35),"")) | M35: =IF($Q35=0,"",IF($T35<>$T34,$T35,"")) | N35: =IF($Q35=0,"",IF(OR($T35<>$T34,$U35<>$U34),$U35,"")) | O35: =IF($Q35=0,"",INDEX(BD_INSPECCION!E:E,$Q35)) -> LUBRICAR | P35: =IF($Q35=0,"",INDEX(BD_INSPECCION!F:F,$Q35)) -> RODAJES DE DIRECCIÓN | Q35: =IFERROR(MATCH($C$9&"|17",BD_INSPECCION!$G:$G,0),0) -> 19 | R35: =IF($A35=0,"",INDEX(BD_PLAN!C:C,$A35)) -> PM3 - 3000 KM | S35: =IF($A35=0,"",INDEX(BD_PLAN!D:D,$A35)) -> SERVICIO GENERAL | T35: =IF($Q35=0,"",INDEX(BD_INSPECCION!C:C,$Q35)) -> PM1 - 1000 KM | U35: =IF($Q35=0,"",INDEX(BD_INSPECCION!D:D,$Q35)) -> DIRECCIÓN
A36: =IFERROR(MATCH($C$9&"|18",BD_PLAN!$J:$J,0),0) -> 20 | B36: =IF($A36=0,"",IF($R36<>$R35,LEFT($R36,FIND(" ",$R36)-1),"")) | C36: =IF($A36=0,"",IF($R36<>$R35,INDEX(BD_CICLO!$E:$E,MATCH($C$9&"|"&$R36,BD_CICLO!$G:$G,0))&" "&$F$6,"")) | D36: =IF($A36=0,"",IF($R36<>$R35,IFERROR(1/(1/SUMPRODUCT(MAX((REGISTRO!$C$3:$C$2002=$C$6)*(REGISTRO!$H$3:$H$2002=$R36)*REGISTRO!$B$3:$B$2002))),""),"")) | E36: =IF($A36=0,"",IF(OR($R36<>$R35,$S36<>$S35),$S36,"")) | F36: =IF($A36=0,"",INDEX(BD_PLAN!E:E,$A36)) -> GASOLINA 90 OCT | G36: =IF($A36=0,"",INDEX(BD_PLAN!F:F,$A36)) -> 0.25 | H36: =IF($A36=0,"",INDEX(BD_PLAN!G:G,$A36)) -> GL | I36: =IF($A36=0,"",INDEX(BD_PLAN!H:H,$A36)) -> 24 | J36: =IF($A36=0,"",INDEX(BD_PLAN!I:I,$A36)) -> 6 | K36: =IF($A36=0,"",IF($R36<>$R35,SUMIFS(BD_PLAN!$I$3:$I$312,BD_PLAN!$B$3:$B$312,$C$9,BD_PLAN!$C$3:$C$312,$R36),"")) | M36: =IF($Q36=0,"",IF($T36<>$T35,$T36,"")) | N36: =IF($Q36=0,"",IF(OR($T36<>$T35,$U36<>$U35),$U36,"")) -> SUSPENSIÓN DELANTERA | O36: =IF($Q36=0,"",INDEX(BD_INSPECCION!E:E,$Q36)) -> INSPECCIONAR | P36: =IF($Q36=0,"",INDEX(BD_INSPECCION!F:F,$Q36)) -> HORQUILLAS: FUGAS DE RETENES Y FUNCIONAMIENTO | Q36: =IFERROR(MATCH($C$9&"|18",BD_INSPECCION!$G:$G,0),0) -> 20 | R36: =IF($A36=0,"",INDEX(BD_PLAN!C:C,$A36)) -> PM3 - 3000 KM | S36: =IF($A36=0,"",INDEX(BD_PLAN!D:D,$A36)) -> SERVICIO GENERAL | T36: =IF($Q36=0,"",INDEX(BD_INSPECCION!C:C,$Q36)) -> PM1 - 1000 KM | U36: =IF($Q36=0,"",INDEX(BD_INSPECCION!D:D,$Q36)) -> SUSPENSIÓN DELANTERA
A37: =IFERROR(MATCH($C$9&"|19",BD_PLAN!$J:$J,0),0) -> 21 | B37: =IF($A37=0,"",IF($R37<>$R36,LEFT($R37,FIND(" ",$R37)-1),"")) | C37: =IF($A37=0,"",IF($R37<>$R36,INDEX(BD_CICLO!$E:$E,MATCH($C$9&"|"&$R37,BD_CICLO!$G:$G,0))&" "&$F$6,"")) | D37: =IF($A37=0,"",IF($R37<>$R36,IFERROR(1/(1/SUMPRODUCT(MAX((REGISTRO!$C$3:$C$2002=$C$6)*(REGISTRO!$H$3:$H$2002=$R37)*REGISTRO!$B$3:$B$2002))),""),"")) | E37: =IF($A37=0,"",IF(OR($R37<>$R36,$S37<>$S36),$S37,"")) -> COMBUSTIBLE | F37: =IF($A37=0,"",INDEX(BD_PLAN!E:E,$A37)) -> LIMPIA CARBURADOR | G37: =IF($A37=0,"",INDEX(BD_PLAN!F:F,$A37)) -> 0.5 | H37: =IF($A37=0,"",INDEX(BD_PLAN!G:G,$A37)) -> UND. | I37: =IF($A37=0,"",INDEX(BD_PLAN!H:H,$A37)) -> 15 | J37: =IF($A37=0,"",INDEX(BD_PLAN!I:I,$A37)) -> 7.5 | K37: =IF($A37=0,"",IF($R37<>$R36,SUMIFS(BD_PLAN!$I$3:$I$312,BD_PLAN!$B$3:$B$312,$C$9,BD_PLAN!$C$3:$C$312,$R37),"")) | M37: =IF($Q37=0,"",IF($T37<>$T36,$T37,"")) | N37: =IF($Q37=0,"",IF(OR($T37<>$T36,$U37<>$U36),$U37,"")) -> SUSPENSIÓN TRASERA | O37: =IF($Q37=0,"",INDEX(BD_INSPECCION!E:E,$Q37)) -> INSPECCIONAR | P37: =IF($Q37=0,"",INDEX(BD_INSPECCION!F:F,$Q37)) -> MUELLES (HOJAS ROTAS), ABRAZADERAS, BUJES Y AMORTIGUADOR | Q37: =IFERROR(MATCH($C$9&"|19",BD_INSPECCION!$G:$G,0),0) -> 21 | R37: =IF($A37=0,"",INDEX(BD_PLAN!C:C,$A37)) -> PM3 - 3000 KM | S37: =IF($A37=0,"",INDEX(BD_PLAN!D:D,$A37)) -> COMBUSTIBLE | T37: =IF($Q37=0,"",INDEX(BD_INSPECCION!C:C,$Q37)) -> PM1 - 1000 KM | U37: =IF($Q37=0,"",INDEX(BD_INSPECCION!D:D,$Q37)) -> SUSPENSIÓN TRASERA
A38: =IFERROR(MATCH($C$9&"|20",BD_PLAN!$J:$J,0),0) -> 22 | B38: =IF($A38=0,"",IF($R38<>$R37,LEFT($R38,FIND(" ",$R38)-1),"")) -> PM4 | C38: =IF($A38=0,"",IF($R38<>$R37,INDEX(BD_CICLO!$E:$E,MATCH($C$9&"|"&$R38,BD_CICLO!$G:$G,0))&" "&$F$6,"")) -> 4000 KM | D38: =IF($A38=0,"",IF($R38<>$R37,IFERROR(1/(1/SUMPRODUCT(MAX((REGISTRO!$C$3:$C$2002=$C$6)*(REGISTRO!$H$3:$H$2002=$R38)*REGISTRO!$B$3:$B$2002))),""),"")) | E38: =IF($A38=0,"",IF(OR($R38<>$R37,$S38<>$S37),$S38,"")) -> MOTOR | F38: =IF($A38=0,"",INDEX(BD_PLAN!E:E,$A38)) -> ACEITE MOTOR 20W50 4T MINERAL | G38: =IF($A38=0,"",INDEX(BD_PLAN!F:F,$A38)) -> 1.5 | H38: =IF($A38=0,"",INDEX(BD_PLAN!G:G,$A38)) -> L | I38: =IF($A38=0,"",INDEX(BD_PLAN!H:H,$A38)) -> 20 | J38: =IF($A38=0,"",INDEX(BD_PLAN!I:I,$A38)) -> 30 | K38: =IF($A38=0,"",IF($R38<>$R37,SUMIFS(BD_PLAN!$I$3:$I$312,BD_PLAN!$B$3:$B$312,$C$9,BD_PLAN!$C$3:$C$312,$R38),"")) -> 105.25 | M38: =IF($Q38=0,"",IF($T38<>$T37,$T38,"")) | N38: =IF($Q38=0,"",IF(OR($T38<>$T37,$U38<>$U37),$U38,"")) -> CONTROLES | O38: =IF($Q38=0,"",INDEX(BD_INSPECCION!E:E,$Q38)) -> LUBRICAR | P38: =IF($Q38=0,"",INDEX(BD_INSPECCION!F:F,$Q38)) -> MANIJAS Y CABLES DE FRENO, EMBRAGUE Y ACELERADOR | Q38: =IFERROR(MATCH($C$9&"|20",BD_INSPECCION!$G:$G,0),0) -> 22 | R38: =IF($A38=0,"",INDEX(BD_PLAN!C:C,$A38)) -> PM4 - 4000 KM | S38: =IF($A38=0,"",INDEX(BD_PLAN!D:D,$A38)) -> MOTOR | T38: =IF($Q38=0,"",INDEX(BD_INSPECCION!C:C,$Q38)) -> PM1 - 1000 KM | U38: =IF($Q38=0,"",INDEX(BD_INSPECCION!D:D,$Q38)) -> CONTROLES
A39: =IFERROR(MATCH($C$9&"|21",BD_PLAN!$J:$J,0),0) -> 23 | B39: =IF($A39=0,"",IF($R39<>$R38,LEFT($R39,FIND(" ",$R39)-1),"")) | C39: =IF($A39=0,"",IF($R39<>$R38,INDEX(BD_CICLO!$E:$E,MATCH($C$9&"|"&$R39,BD_CICLO!$G:$G,0))&" "&$F$6,"")) | D39: =IF($A39=0,"",IF($R39<>$R38,IFERROR(1/(1/SUMPRODUCT(MAX((REGISTRO!$C$3:$C$2002=$C$6)*(REGISTRO!$H$3:$H$2002=$R39)*REGISTRO!$B$3:$B$2002))),""),"")) | E39: =IF($A39=0,"",IF(OR($R39<>$R38,$S39<>$S38),$S39,"")) | F39: =IF($A39=0,"",INDEX(BD_PLAN!E:E,$A39)) -> ARANDELA TAPÓN DE DRENAJE | G39: =IF($A39=0,"",INDEX(BD_PLAN!F:F,$A39)) -> 1 | H39: =IF($A39=0,"",INDEX(BD_PLAN!G:G,$A39)) -> UND. | I39: =IF($A39=0,"",INDEX(BD_PLAN!H:H,$A39)) -> 2 | J39: =IF($A39=0,"",INDEX(BD_PLAN!I:I,$A39)) -> 2 | K39: =IF($A39=0,"",IF($R39<>$R38,SUMIFS(BD_PLAN!$I$3:$I$312,BD_PLAN!$B$3:$B$312,$C$9,BD_PLAN!$C$3:$C$312,$R39),"")) | M39: =IF($Q39=0,"",IF($T39<>$T38,$T39,"")) | N39: =IF($Q39=0,"",IF(OR($T39<>$T38,$U39<>$U38),$U39,"")) -> RUEDAS | O39: =IF($Q39=0,"",INDEX(BD_INSPECCION!E:E,$Q39)) -> INSPECCIONAR | P39: =IF($Q39=0,"",INDEX(BD_INSPECCION!F:F,$Q39)) -> PRESIÓN, DESGASTE DE LLANTAS Y AJUSTE DE TUERCAS | Q39: =IFERROR(MATCH($C$9&"|21",BD_INSPECCION!$G:$G,0),0) -> 23 | R39: =IF($A39=0,"",INDEX(BD_PLAN!C:C,$A39)) -> PM4 - 4000 KM | S39: =IF($A39=0,"",INDEX(BD_PLAN!D:D,$A39)) -> MOTOR | T39: =IF($Q39=0,"",INDEX(BD_INSPECCION!C:C,$Q39)) -> PM1 - 1000 KM | U39: =IF($Q39=0,"",INDEX(BD_INSPECCION!D:D,$Q39)) -> RUEDAS
A40: =IFERROR(MATCH($C$9&"|22",BD_PLAN!$J:$J,0),0) -> 24 | B40: =IF($A40=0,"",IF($R40<>$R39,LEFT($R40,FIND(" ",$R40)-1),"")) | C40: =IF($A40=0,"",IF($R40<>$R39,INDEX(BD_CICLO!$E:$E,MATCH($C$9&"|"&$R40,BD_CICLO!$G:$G,0))&" "&$F$6,"")) | D40: =IF($A40=0,"",IF($R40<>$R39,IFERROR(1/(1/SUMPRODUCT(MAX((REGISTRO!$C$3:$C$2002=$C$6)*(REGISTRO!$H$3:$H$2002=$R40)*REGISTRO!$B$3:$B$2002))),""),"")) | E40: =IF($A40=0,"",IF(OR($R40<>$R39,$S40<>$S39),$S40,"")) -> COMBUSTIBLE | F40: =IF($A40=0,"",INDEX(BD_PLAN!E:E,$A40)) -> FILTRO DE GASOLINA EN LÍNEA | G40: =IF($A40=0,"",INDEX(BD_PLAN!F:F,$A40)) -> 1 | H40: =IF($A40=0,"",INDEX(BD_PLAN!G:G,$A40)) -> UND. | I40: =IF($A40=0,"",INDEX(BD_PLAN!H:H,$A40)) -> 8 | J40: =IF($A40=0,"",INDEX(BD_PLAN!I:I,$A40)) -> 8 | K40: =IF($A40=0,"",IF($R40<>$R39,SUMIFS(BD_PLAN!$I$3:$I$312,BD_PLAN!$B$3:$B$312,$C$9,BD_PLAN!$C$3:$C$312,$R40),"")) | M40: =IF($Q40=0,"",IF($T40<>$T39,$T40,"")) | N40: =IF($Q40=0,"",IF(OR($T40<>$T39,$U40<>$U39),$U40,"")) -> SISTEMA ELÉCTRICO | O40: =IF($Q40=0,"",INDEX(BD_INSPECCION!E:E,$Q40)) -> INSPECCIONAR | P40: =IF($Q40=0,"",INDEX(BD_INSPECCION!F:F,$Q40)) -> BATERÍA, BORNES, LUCES, CLAXON E INTERRUPTORES | Q40: =IFERROR(MATCH($C$9&"|22",BD_INSPECCION!$G:$G,0),0) -> 24 | R40: =IF($A40=0,"",INDEX(BD_PLAN!C:C,$A40)) -> PM4 - 4000 KM | S40: =IF($A40=0,"",INDEX(BD_PLAN!D:D,$A40)) -> COMBUSTIBLE | T40: =IF($Q40=0,"",INDEX(BD_INSPECCION!C:C,$Q40)) -> PM1 - 1000 KM | U40: =IF($Q40=0,"",INDEX(BD_INSPECCION!D:D,$Q40)) -> SISTEMA ELÉCTRICO
A41: =IFERROR(MATCH($C$9&"|23",BD_PLAN!$J:$J,0),0) -> 25 | B41: =IF($A41=0,"",IF($R41<>$R40,LEFT($R41,FIND(" ",$R41)-1),"")) | C41: =IF($A41=0,"",IF($R41<>$R40,INDEX(BD_CICLO!$E:$E,MATCH($C$9&"|"&$R41,BD_CICLO!$G:$G,0))&" "&$F$6,"")) | D41: =IF($A41=0,"",IF($R41<>$R40,IFERROR(1/(1/SUMPRODUCT(MAX((REGISTRO!$C$3:$C$2002=$C$6)*(REGISTRO!$H$3:$H$2002=$R41)*REGISTRO!$B$3:$B$2002))),""),"")) | E41: =IF($A41=0,"",IF(OR($R41<>$R40,$S41<>$S40),$S41,"")) | F41: =IF($A41=0,"",INDEX(BD_PLAN!E:E,$A41)) -> LIMPIA CARBURADOR | G41: =IF($A41=0,"",INDEX(BD_PLAN!F:F,$A41)) -> 0.5 | H41: =IF($A41=0,"",INDEX(BD_PLAN!G:G,$A41)) -> UND. | I41: =IF($A41=0,"",INDEX(BD_PLAN!H:H,$A41)) -> 15 | J41: =IF($A41=0,"",INDEX(BD_PLAN!I:I,$A41)) -> 7.5 | K41: =IF($A41=0,"",IF($R41<>$R40,SUMIFS(BD_PLAN!$I$3:$I$312,BD_PLAN!$B$3:$B$312,$C$9,BD_PLAN!$C$3:$C$312,$R41),"")) | M41: =IF($Q41=0,"",IF($T41<>$T40,$T41,"")) | N41: =IF($Q41=0,"",IF(OR($T41<>$T40,$U41<>$U40),$U41,"")) -> CHASIS / TOLVA | O41: =IF($Q41=0,"",INDEX(BD_INSPECCION!E:E,$Q41)) -> INSPECCIONAR | P41: =IF($Q41=0,"",INDEX(BD_INSPECCION!F:F,$Q41)) -> SOLDADURAS, PERNOS DE TOLVA Y BASTIDOR | Q41: =IFERROR(MATCH($C$9&"|23",BD_INSPECCION!$G:$G,0),0) -> 25 | R41: =IF($A41=0,"",INDEX(BD_PLAN!C:C,$A41)) -> PM4 - 4000 KM | S41: =IF($A41=0,"",INDEX(BD_PLAN!D:D,$A41)) -> COMBUSTIBLE | T41: =IF($Q41=0,"",INDEX(BD_INSPECCION!C:C,$Q41)) -> PM1 - 1000 KM | U41: =IF($Q41=0,"",INDEX(BD_INSPECCION!D:D,$Q41)) -> CHASIS / TOLVA
A42: =IFERROR(MATCH($C$9&"|24",BD_PLAN!$J:$J,0),0) -> 26 | B42: =IF($A42=0,"",IF($R42<>$R41,LEFT($R42,FIND(" ",$R42)-1),"")) | C42: =IF($A42=0,"",IF($R42<>$R41,INDEX(BD_CICLO!$E:$E,MATCH($C$9&"|"&$R42,BD_CICLO!$G:$G,0))&" "&$F$6,"")) | D42: =IF($A42=0,"",IF($R42<>$R41,IFERROR(1/(1/SUMPRODUCT(MAX((REGISTRO!$C$3:$C$2002=$C$6)*(REGISTRO!$H$3:$H$2002=$R42)*REGISTRO!$B$3:$B$2002))),""),"")) | E42: =IF($A42=0,"",IF(OR($R42<>$R41,$S42<>$S41),$S42,"")) -> ADMISIÓN DE AIRE | F42: =IF($A42=0,"",INDEX(BD_PLAN!E:E,$A42)) -> FILTRO DE AIRE MAVILA CARGO 250 | G42: =IF($A42=0,"",INDEX(BD_PLAN!F:F,$A42)) -> 1 | H42: =IF($A42=0,"",INDEX(BD_PLAN!G:G,$A42)) -> UND. | I42: =IF($A42=0,"",INDEX(BD_PLAN!H:H,$A42)) -> 30 | J42: =IF($A42=0,"",INDEX(BD_PLAN!I:I,$A42)) -> 30 | K42: =IF($A42=0,"",IF($R42<>$R41,SUMIFS(BD_PLAN!$I$3:$I$312,BD_PLAN!$B$3:$B$312,$C$9,BD_PLAN!$C$3:$C$312,$R42),"")) | M42: =IF($Q42=0,"",IF($T42<>$T41,$T42,"")) -> PM2 - 2000 KM | N42: =IF($Q42=0,"",IF(OR($T42<>$T41,$U42<>$U41),$U42,"")) -> MOTOR | O42: =IF($Q42=0,"",INDEX(BD_INSPECCION!E:E,$Q42)) -> INSPECCIONAR | P42: =IF($Q42=0,"",INDEX(BD_INSPECCION!F:F,$Q42)) -> LUZ DE VÁLVULAS (REGULAR SI ES NECESARIO) | Q42: =IFERROR(MATCH($C$9&"|24",BD_INSPECCION!$G:$G,0),0) -> 26 | R42: =IF($A42=0,"",INDEX(BD_PLAN!C:C,$A42)) -> PM4 - 4000 KM | S42: =IF($A42=0,"",INDEX(BD_PLAN!D:D,$A42)) -> ADMISIÓN DE AIRE | T42: =IF($Q42=0,"",INDEX(BD_INSPECCION!C:C,$Q42)) -> PM2 - 2000 KM | U42: =IF($Q42=0,"",INDEX(BD_INSPECCION!D:D,$Q42)) -> MOTOR
A43: =IFERROR(MATCH($C$9&"|25",BD_PLAN!$J:$J,0),0) -> 27 | B43: =IF($A43=0,"",IF($R43<>$R42,LEFT($R43,FIND(" ",$R43)-1),"")) | C43: =IF($A43=0,"",IF($R43<>$R42,INDEX(BD_CICLO!$E:$E,MATCH($C$9&"|"&$R43,BD_CICLO!$G:$G,0))&" "&$F$6,"")) | D43: =IF($A43=0,"",IF($R43<>$R42,IFERROR(1/(1/SUMPRODUCT(MAX((REGISTRO!$C$3:$C$2002=$C$6)*(REGISTRO!$H$3:$H$2002=$R43)*REGISTRO!$B$3:$B$2002))),""),"")) | E43: =IF($A43=0,"",IF(OR($R43<>$R42,$S43<>$S42),$S43,"")) -> ENCENDIDO | F43: =IF($A43=0,"",INDEX(BD_PLAN!E:E,$A43)) -> BUJÍA MAVILA CARGO 250 | G43: =IF($A43=0,"",INDEX(BD_PLAN!F:F,$A43)) -> 1 | H43: =IF($A43=0,"",INDEX(BD_PLAN!G:G,$A43)) -> UND. | I43: =IF($A43=0,"",INDEX(BD_PLAN!H:H,$A43)) -> 12 | J43: =IF($A43=0,"",INDEX(BD_PLAN!I:I,$A43)) -> 12 | K43: =IF($A43=0,"",IF($R43<>$R42,SUMIFS(BD_PLAN!$I$3:$I$312,BD_PLAN!$B$3:$B$312,$C$9,BD_PLAN!$C$3:$C$312,$R43),"")) | M43: =IF($Q43=0,"",IF($T43<>$T42,$T43,"")) | N43: =IF($Q43=0,"",IF(OR($T43<>$T42,$U43<>$U42),$U43,"")) | O43: =IF($Q43=0,"",INDEX(BD_INSPECCION!E:E,$Q43)) -> INSPECCIONAR | P43: =IF($Q43=0,"",INDEX(BD_INSPECCION!F:F,$Q43)) -> VELOCIDAD DE RALENTÍ | Q43: =IFERROR(MATCH($C$9&"|25",BD_INSPECCION!$G:$G,0),0) -> 27 | R43: =IF($A43=0,"",INDEX(BD_PLAN!C:C,$A43)) -> PM4 - 4000 KM | S43: =IF($A43=0,"",INDEX(BD_PLAN!D:D,$A43)) -> ENCENDIDO | T43: =IF($Q43=0,"",INDEX(BD_INSPECCION!C:C,$Q43)) -> PM2 - 2000 KM | U43: =IF($Q43=0,"",INDEX(BD_INSPECCION!D:D,$Q43)) -> MOTOR
A44: =IFERROR(MATCH($C$9&"|26",BD_PLAN!$J:$J,0),0) -> 28 | B44: =IF($A44=0,"",IF($R44<>$R43,LEFT($R44,FIND(" ",$R44)-1),"")) | C44: =IF($A44=0,"",IF($R44<>$R43,INDEX(BD_CICLO!$E:$E,MATCH($C$9&"|"&$R44,BD_CICLO!$G:$G,0))&" "&$F$6,"")) | D44: =IF($A44=0,"",IF($R44<>$R43,IFERROR(1/(1/SUMPRODUCT(MAX((REGISTRO!$C$3:$C$2002=$C$6)*(REGISTRO!$H$3:$H$2002=$R44)*REGISTRO!$B$3:$B$2002))),""),"")) | E44: =IF($A44=0,"",IF(OR($R44<>$R43,$S44<>$S43),$S44,"")) -> CHASIS | F44: =IF($A44=0,"",INDEX(BD_PLAN!E:E,$A44)) -> GRASA MULTIPROPÓSITO | G44: =IF($A44=0,"",INDEX(BD_PLAN!F:F,$A44)) -> 0.5 | H44: =IF($A44=0,"",INDEX(BD_PLAN!G:G,$A44)) -> LBRS | I44: =IF($A44=0,"",INDEX(BD_PLAN!H:H,$A44)) -> 15 | J44: =IF($A44=0,"",INDEX(BD_PLAN!I:I,$A44)) -> 7.5 | K44: =IF($A44=0,"",IF($R44<>$R43,SUMIFS(BD_PLAN!$I$3:$I$312,BD_PLAN!$B$3:$B$312,$C$9,BD_PLAN!$C$3:$C$312,$R44),"")) | M44: =IF($Q44=0,"",IF($T44<>$T43,$T44,"")) | N44: =IF($Q44=0,"",IF(OR($T44<>$T43,$U44<>$U43),$U44,"")) | O44: =IF($Q44=0,"",INDEX(BD_INSPECCION!E:E,$Q44)) -> INSPECCIONAR | P44: =IF($Q44=0,"",INDEX(BD_INSPECCION!F:F,$Q44)) -> FUGAS DE ACEITE Y ESTADO DE EMPAQUES | Q44: =IFERROR(MATCH($C$9&"|26",BD_INSPECCION!$G:$G,0),0) -> 28 | R44: =IF($A44=0,"",INDEX(BD_PLAN!C:C,$A44)) -> PM4 - 4000 KM | S44: =IF($A44=0,"",INDEX(BD_PLAN!D:D,$A44)) -> CHASIS | T44: =IF($Q44=0,"",INDEX(BD_INSPECCION!C:C,$Q44)) -> PM2 - 2000 KM | U44: =IF($Q44=0,"",INDEX(BD_INSPECCION!D:D,$Q44)) -> MOTOR
A45: =IFERROR(MATCH($C$9&"|27",BD_PLAN!$J:$J,0),0) -> 29 | B45: =IF($A45=0,"",IF($R45<>$R44,LEFT($R45,FIND(" ",$R45)-1),"")) | C45: =IF($A45=0,"",IF($R45<>$R44,INDEX(BD_CICLO!$E:$E,MATCH($C$9&"|"&$R45,BD_CICLO!$G:$G,0))&" "&$F$6,"")) | D45: =IF($A45=0,"",IF($R45<>$R44,IFERROR(1/(1/SUMPRODUCT(MAX((REGISTRO!$C$3:$C$2002=$C$6)*(REGISTRO!$H$3:$H$2002=$R45)*REGISTRO!$B$3:$B$2002))),""),"")) | E45: =IF($A45=0,"",IF(OR($R45<>$R44,$S45<>$S44),$S45,"")) -> SERVICIO GENERAL | F45: =IF($A45=0,"",INDEX(BD_PLAN!E:E,$A45)) -> TRAPO INDUSTRIAL | G45: =IF($A45=0,"",INDEX(BD_PLAN!F:F,$A45)) -> 0.5 | H45: =IF($A45=0,"",INDEX(BD_PLAN!G:G,$A45)) -> KG | I45: =IF($A45=0,"",INDEX(BD_PLAN!H:H,$A45)) -> 4.5 | J45: =IF($A45=0,"",INDEX(BD_PLAN!I:I,$A45)) -> 2.25 | K45: =IF($A45=0,"",IF($R45<>$R44,SUMIFS(BD_PLAN!$I$3:$I$312,BD_PLAN!$B$3:$B$312,$C$9,BD_PLAN!$C$3:$C$312,$R45),"")) | M45: =IF($Q45=0,"",IF($T45<>$T44,$T45,"")) | N45: =IF($Q45=0,"",IF(OR($T45<>$T44,$U45<>$U44),$U45,"")) | O45: =IF($Q45=0,"",INDEX(BD_INSPECCION!E:E,$Q45)) -> LIMPIAR | P45: =IF($Q45=0,"",INDEX(BD_INSPECCION!F:F,$Q45)) -> MALLA (COLADOR) DE ACEITE | Q45: =IFERROR(MATCH($C$9&"|27",BD_INSPECCION!$G:$G,0),0) -> 29 | R45: =IF($A45=0,"",INDEX(BD_PLAN!C:C,$A45)) -> PM4 - 4000 KM | S45: =IF($A45=0,"",INDEX(BD_PLAN!D:D,$A45)) -> SERVICIO GENERAL | T45: =IF($Q45=0,"",INDEX(BD_INSPECCION!C:C,$Q45)) -> PM2 - 2000 KM | U45: =IF($Q45=0,"",INDEX(BD_INSPECCION!D:D,$Q45)) -> MOTOR
...

Sheet FORMATO
B2: FORMATO DE MANTENIMIENTO PREVENTIVO
B4: EQUIPO | C4: 04101 - VL001- TRIMOTO MAVILA 1 - CAMPO | L4: =MATCH(LEFT(C4,5),EQUIPOS!$B$3:$B$18,0)+2 -> 3
B5: MANTENIMIENTO | C5: PM1 - 1000 KM | E5: PROGRAMADO A | F5: =IFERROR(INDEX(BD_CICLO!$E:$E,MATCH($L$5&"|"&$C$5,BD_CICLO!$G:$G,0))&" "&$L$6,"") -> 1000 KM | H5: N° OT | L5: =INDEX(EQUIPOS!F:F,$L$4) -> TRIMOTO MAVILA CARGO 250
B6: FECHA | E6: KM / HORÓMETRO REAL | L6: =INDEX(EQUIPOS!G:G,$L$4) -> KM
B7: TÉCNICO | E7: HORA INICIO / FIN
B9: MATERIALES A CAMBIAR
B10: SISTEMA | C10: MATERIAL | F10: CANT. | G10: UND. | H10: CAMBIADO | J10: CANT. USADA
B11: =IF($L11=0,"",$M11) -> MOTOR | C11: =IF($L11=0,"",INDEX(BD_PLAN!E:E,$L11)) -> ACEITE MOTOR 20W50 4T MINERAL | F11: =IF($L11=0,"",INDEX(BD_PLAN!F:F,$L11)) -> 1.5 | G11: =IF($L11=0,"",INDEX(BD_PLAN!G:G,$L11)) -> L | H11: =IF($L11=0,"","SI ☐ NO ☐") -> SI ☐ NO ☐ | L11: =IFERROR(MATCH($L$5&"|"&$C$5&"|1",BD_PLAN!$K:$K,0),0) -> 3 | M11: =IF($L11=0,"",INDEX(BD_PLAN!D:D,$L11)) -> MOTOR
B12: =IF($L12=0,"",IF($M12<>$M11,$M12,"")) | C12: =IF($L12=0,"",INDEX(BD_PLAN!E:E,$L12)) -> ARANDELA TAPÓN DE DRENAJE | F12: =IF($L12=0,"",INDEX(BD_PLAN!F:F,$L12)) -> 1 | G12: =IF($L12=0,"",INDEX(BD_PLAN!G:G,$L12)) -> UND. | H12: =IF($L12=0,"","SI ☐ NO ☐") -> SI ☐ NO ☐ | L12: =IFERROR(MATCH($L$5&"|"&$C$5&"|2",BD_PLAN!$K:$K,0),0) -> 4 | M12: =IF($L12=0,"",INDEX(BD_PLAN!D:D,$L12)) -> MOTOR
B13: =IF($L13=0,"",IF($M13<>$M12,$M13,"")) -> CHASIS | C13: =IF($L13=0,"",INDEX(BD_PLAN!E:E,$L13)) -> GRASA MULTIPROPÓSITO | F13: =IF($L13=0,"",INDEX(BD_PLAN!F:F,$L13)) -> 0.5 | G13: =IF($L13=0,"",INDEX(BD_PLAN!G:G,$L13)) -> LBRS | H13: =IF($L13=0,"","SI ☐ NO ☐") -> SI ☐ NO ☐ | L13: =IFERROR(MATCH($L$5&"|"&$C$5&"|3",BD_PLAN!$K:$K,0),0) -> 5 | M13: =IF($L13=0,"",INDEX(BD_PLAN!D:D,$L13)) -> CHASIS
B14: =IF($L14=0,"",IF($M14<>$M13,$M14,"")) -> SERVICIO GENERAL | C14: =IF($L14=0,"",INDEX(BD_PLAN!E:E,$L14)) -> TRAPO INDUSTRIAL | F14: =IF($L14=0,"",INDEX(BD_PLAN!F:F,$L14)) -> 0.5 | G14: =IF($L14=0,"",INDEX(BD_PLAN!G:G,$L14)) -> KG | H14: =IF($L14=0,"","SI ☐ NO ☐") -> SI ☐ NO ☐ | L14: =IFERROR(MATCH($L$5&"|"&$C$5&"|4",BD_PLAN!$K:$K,0),0) -> 6 | M14: =IF($L14=0,"",INDEX(BD_PLAN!D:D,$L14)) -> SERVICIO GENERAL
B15: =IF($L15=0,"",IF($M15<>$M14,$M15,"")) | C15: =IF($L15=0,"",INDEX(BD_PLAN!E:E,$L15)) -> GASOLINA 90 OCT | F15: =IF($L15=0,"",INDEX(BD_PLAN!F:F,$L15)) -> 0.25 | G15: =IF($L15=0,"",INDEX(BD_PLAN!G:G,$L15)) -> GL | H15: =IF($L15=0,"","SI ☐ NO ☐") -> SI ☐ NO ☐ | L15: =IFERROR(MATCH($L$5&"|"&$C$5&"|5",BD_PLAN!$K:$K,0),0) -> 7 | M15: =IF($L15=0,"",INDEX(BD_PLAN!D:D,$L15)) -> SERVICIO GENERAL
B16: =IF($L16=0,"",IF($M16<>$M15,$M16,"")) -> COMBUSTIBLE | C16: =IF($L16=0,"",INDEX(BD_PLAN!E:E,$L16)) -> LIMPIA CARBURADOR | F16: =IF($L16=0,"",INDEX(BD_PLAN!F:F,$L16)) -> 0.5 | G16: =IF($L16=0,"",INDEX(BD_PLAN!G:G,$L16)) -> UND. | H16: =IF($L16=0,"","SI ☐ NO ☐") -> SI ☐ NO ☐ | L16: =IFERROR(MATCH($L$5&"|"&$C$5&"|6",BD_PLAN!$K:$K,0),0) -> 8 | M16: =IF($L16=0,"",INDEX(BD_PLAN!D:D,$L16)) -> COMBUSTIBLE
B17: =IF($L17=0,"",IF($M17<>$M16,$M17,"")) | C17: =IF($L17=0,"",INDEX(BD_PLAN!E:E,$L17)) | F17: =IF($L17=0,"",INDEX(BD_PLAN!F:F,$L17)) | G17: =IF($L17=0,"",INDEX(BD_PLAN!G:G,$L17)) | H17: =IF($L17=0,"","SI ☐ NO ☐") | L17: =IFERROR(MATCH($L$5&"|"&$C$5&"|7",BD_PLAN!$K:$K,0),0) -> 0 | M17: =IF($L17=0,"",INDEX(BD_PLAN!D:D,$L17))
B18: =IF($L18=0,"",IF($M18<>$M17,$M18,"")) | C18: =IF($L18=0,"",INDEX(BD_PLAN!E:E,$L18)) | F18: =IF($L18=0,"",INDEX(BD_PLAN!F:F,$L18)) | G18: =IF($L18=0,"",INDEX(BD_PLAN!G:G,$L18)) | H18: =IF($L18=0,"","SI ☐ NO ☐") | L18: =IFERROR(MATCH($L$5&"|"&$C$5&"|8",BD_PLAN!$K:$K,0),0) -> 0 | M18: =IF($L18=0,"",INDEX(BD_PLAN!D:D,$L18))
B19: =IF($L19=0,"",IF($M19<>$M18,$M19,"")) | C19: =IF($L19=0,"",INDEX(BD_PLAN!E:E,$L19)) | F19: =IF($L19=0,"",INDEX(BD_PLAN!F:F,$L19)) | G19: =IF($L19=0,"",INDEX(BD_PLAN!G:G,$L19)) | H19: =IF($L19=0,"","SI ☐ NO ☐") | L19: =IFERROR(MATCH($L$5&"|"&$C$5&"|9",BD_PLAN!$K:$K,0),0) -> 0 | M19: =IF($L19=0,"",INDEX(BD_PLAN!D:D,$L19))
B20: =IF($L20=0,"",IF($M20<>$M19,$M20,"")) | C20: =IF($L20=0,"",INDEX(BD_PLAN!E:E,$L20)) | F20: =IF($L20=0,"",INDEX(BD_PLAN!F:F,$L20)) | G20: =IF($L20=0,"",INDEX(BD_PLAN!G:G,$L20)) | H20: =IF($L20=0,"","SI ☐ NO ☐") | L20: =IFERROR(MATCH($L$5&"|"&$C$5&"|10",BD_PLAN!$K:$K,0),0) -> 0 | M20: =IF($L20=0,"",INDEX(BD_PLAN!D:D,$L20))
B21: =IF($L21=0,"",IF($M21<>$M20,$M21,"")) | C21: =IF($L21=0,"",INDEX(BD_PLAN!E:E,$L21)) | F21: =IF($L21=0,"",INDEX(BD_PLAN!F:F,$L21)) | G21: =IF($L21=0,"",INDEX(BD_PLAN!G:G,$L21)) | H21: =IF($L21=0,"","SI ☐ NO ☐") | L21: =IFERROR(MATCH($L$5&"|"&$C$5&"|11",BD_PLAN!$K:$K,0),0) -> 0 | M21: =IF($L21=0,"",INDEX(BD_PLAN!D:D,$L21))
B22: =IF($L22=0,"",IF($M22<>$M21,$M22,"")) | C22: =IF($L22=0,"",INDEX(BD_PLAN!E:E,$L22)) | F22: =IF($L22=0,"",INDEX(BD_PLAN!F:F,$L22)) | G22: =IF($L22=0,"",INDEX(BD_PLAN!G:G,$L22)) | H22: =IF($L22=0,"","SI ☐ NO ☐") | L22: =IFERROR(MATCH($L$5&"|"&$C$5&"|12",BD_PLAN!$K:$K,0),0) -> 0 | M22: =IF($L22=0,"",INDEX(BD_PLAN!D:D,$L22))
B23: =IF($L23=0,"",IF($M23<>$M22,$M23,"")) | C23: =IF($L23=0,"",INDEX(BD_PLAN!E:E,$L23)) | F23: =IF($L23=0,"",INDEX(BD_PLAN!F:F,$L23)) | G23: =IF($L23=0,"",INDEX(BD_PLAN!G:G,$L23)) | H23: =IF($L23=0,"","SI ☐ NO ☐") | L23: =IFERROR(MATCH($L$5&"|"&$C$5&"|13",BD_PLAN!$K:$K,0),0) -> 0 | M23: =IF($L23=0,"",INDEX(BD_PLAN!D:D,$L23))
B24: =IF($L24=0,"",IF($M24<>$M23,$M24,"")) | C24: =IF($L24=0,"",INDEX(BD_PLAN!E:E,$L24)) | F24: =IF($L24=0,"",INDEX(BD_PLAN!F:F,$L24)) | G24: =IF($L24=0,"",INDEX(BD_PLAN!G:G,$L24)) | H24: =IF($L24=0,"","SI ☐ NO ☐") | L24: =IFERROR(MATCH($L$5&"|"&$C$5&"|14",BD_PLAN!$K:$K,0),0) -> 0 | M24: =IF($L24=0,"",INDEX(BD_PLAN!D:D,$L24))
B26: CHECK LIST DE INSPECCIÓN
B27: SISTEMA | C27: ACTIVIDAD | D27: TAREA | G27: OK | H27: NO OK | I27: OBSERVACIÓN
B28: =IF($L28=0,"",$M28) -> MOTOR | C28: =IF($L28=0,"",INDEX(BD_INSPECCION!E:E,$L28)) -> INSPECCIONAR | D28: =IF($L28=0,"",INDEX(BD_INSPECCION!F:F,$L28)) -> LUZ DE VÁLVULAS (REGULAR SI ES NECESARIO) | G28: =IF($L28=0,"","☐") -> ☐ | H28: =IF($L28=0,"","☐") -> ☐ | L28: =IFERROR(MATCH($L$5&"|"&$C$5&"|1",BD_INSPECCION!$H:$H,0),0) -> 3 | M28: =IF($L28=0,"",INDEX(BD_INSPECCION!D:D,$L28)) -> MOTOR
B29: =IF($L29=0,"",IF($M29<>$M28,$M29,"")) | C29: =IF($L29=0,"",INDEX(BD_INSPECCION!E:E,$L29)) -> INSPECCIONAR | D29: =IF($L29=0,"",INDEX(BD_INSPECCION!F:F,$L29)) -> VELOCIDAD DE RALENTÍ | G29: =IF($L29=0,"","☐") -> ☐ | H29: =IF($L29=0,"","☐") -> ☐ | L29: =IFERROR(MATCH($L$5&"|"&$C$5&"|2",BD_INSPECCION!$H:$H,0),0) -> 4 | M29: =IF($L29=0,"",INDEX(BD_INSPECCION!D:D,$L29)) -> MOTOR
B30: =IF($L30=0,"",IF($M30<>$M29,$M30,"")) | C30: =IF($L30=0,"",INDEX(BD_INSPECCION!E:E,$L30)) -> INSPECCIONAR | D30: =IF($L30=0,"",INDEX(BD_INSPECCION!F:F,$L30)) -> FUGAS DE ACEITE Y ESTADO DE EMPAQUES | G30: =IF($L30=0,"","☐") -> ☐ | H30: =IF($L30=0,"","☐") -> ☐ | L30: =IFERROR(MATCH($L$5&"|"&$C$5&"|3",BD_INSPECCION!$H:$H,0),0) -> 5 | M30: =IF($L30=0,"",INDEX(BD_INSPECCION!D:D,$L30)) -> MOTOR
B31: =IF($L31=0,"",IF($M31<>$M30,$M31,"")) | C31: =IF($L31=0,"",INDEX(BD_INSPECCION!E:E,$L31)) -> LIMPIAR | D31: =IF($L31=0,"",INDEX(BD_INSPECCION!F:F,$L31)) -> MALLA (COLADOR) DE ACEITE | G31: =IF($L31=0,"","☐") -> ☐ | H31: =IF($L31=0,"","☐") -> ☐ | L31: =IFERROR(MATCH($L$5&"|"&$C$5&"|4",BD_INSPECCION!$H:$H,0),0) -> 6 | M31: =IF($L31=0,"",INDEX(BD_INSPECCION!D:D,$L31)) -> MOTOR
B32: =IF($L32=0,"",IF($M32<>$M31,$M32,"")) -> ADMISIÓN DE AIRE | C32: =IF($L32=0,"",INDEX(BD_INSPECCION!E:E,$L32)) -> LIMPIAR | D32: =IF($L32=0,"",INDEX(BD_INSPECCION!F:F,$L32)) -> FILTRO DE AIRE | G32: =IF($L32=0,"","☐") -> ☐ | H32: =IF($L32=0,"","☐") -> ☐ | L32: =IFERROR(MATCH($L$5&"|"&$C$5&"|5",BD_INSPECCION!$H:$H,0),0) -> 7 | M32: =IF($L32=0,"",INDEX(BD_INSPECCION!D:D,$L32)) -> ADMISIÓN DE AIRE
B33: =IF($L33=0,"",IF($M33<>$M32,$M33,"")) -> COMBUSTIBLE | C33: =IF($L33=0,"",INDEX(BD_INSPECCION!E:E,$L33)) -> INSPECCIONAR | D33: =IF($L33=0,"",INDEX(BD_INSPECCION!F:F,$L33)) -> MANGUERA DE COMBUSTIBLE (GRIETAS Y FUGAS) | G33: =IF($L33=0,"","☐") -> ☐ | H33: =IF($L33=0,"","☐") -> ☐ | L33: =IFERROR(MATCH($L$5&"|"&$C$5&"|6",BD_INSPECCION!$H:$H,0),0) -> 8 | M33: =IF($L33=0,"",INDEX(BD_INSPECCION!D:D,$L33)) -> COMBUSTIBLE
B34: =IF($L34=0,"",IF($M34<>$M33,$M34,"")) | C34: =IF($L34=0,"",INDEX(BD_INSPECCION!E:E,$L34)) -> INSPECCIONAR | D34: =IF($L34=0,"",INDEX(BD_INSPECCION!F:F,$L34)) -> FUNCIONAMIENTO DEL ACELERADOR Y CHOKE | G34: =IF($L34=0,"","☐") -> ☐ | H34: =IF($L34=0,"","☐") -> ☐ | L34: =IFERROR(MATCH($L$5&"|"&$C$5&"|7",BD_INSPECCION!$H:$H,0),0) -> 9 | M34: =IF($L34=0,"",INDEX(BD_INSPECCION!D:D,$L34)) -> COMBUSTIBLE
B35: =IF($L35=0,"",IF($M35<>$M34,$M35,"")) -> ENCENDIDO | C35: =IF($L35=0,"",INDEX(BD_INSPECCION!E:E,$L35)) -> INSPECCIONAR | D35: =IF($L35=0,"",INDEX(BD_INSPECCION!F:F,$L35)) -> BUJÍA: LIMPIAR Y CALIBRAR | G35: =IF($L35=0,"","☐") -> ☐ | H35: =IF($L35=0,"","☐") -> ☐ | L35: =IFERROR(MATCH($L$5&"|"&$C$5&"|8",BD_INSPECCION!$H:$H,0),0) -> 10 | M35: =IF($L35=0,"",INDEX(BD_INSPECCION!D:D,$L35)) -> ENCENDIDO
B36: =IF($L36=0,"",IF($M36<>$M35,$M36,"")) -> TRANSMISIÓN | C36: =IF($L36=0,"",INDEX(BD_INSPECCION!E:E,$L36)) -> INSPECCIONAR | D36: =IF($L36=0,"",INDEX(BD_INSPECCION!F:F,$L36)) -> EMBRAGUE (JUEGO LIBRE DEL CABLE) Y CAMBIOS | G36: =IF($L36=0,"","☐") -> ☐ | H36: =IF($L36=0,"","☐") -> ☐ | L36: =IFERROR(MATCH($L$5&"|"&$C$5&"|9",BD_INSPECCION!$H:$H,0),0) -> 11 | M36: =IF($L36=0,"",INDEX(BD_INSPECCION!D:D,$L36)) -> TRANSMISIÓN
B37: =IF($L37=0,"",IF($M37<>$M36,$M37,"")) -> CARDÁN | C37: =IF($L37=0,"",INDEX(BD_INSPECCION!E:E,$L37)) -> INSPECCIONAR | D37: =IF($L37=0,"",INDEX(BD_INSPECCION!F:F,$L37)) -> CRUCETAS (JUEGO) Y GUARDAPOLVOS | G37: =IF($L37=0,"","☐") -> ☐ | H37: =IF($L37=0,"","☐") -> ☐ | L37: =IFERROR(MATCH($L$5&"|"&$C$5&"|10",BD_INSPECCION!$H:$H,0),0) -> 12 | M37: =IF($L37=0,"",INDEX(BD_INSPECCION!D:D,$L37)) -> CARDÁN
B38: =IF($L38=0,"",IF($M38<>$M37,$M38,"")) | C38: =IF($L38=0,"",INDEX(BD_INSPECCION!E:E,$L38)) -> LUBRICAR | D38: =IF($L38=0,"",INDEX(BD_INSPECCION!F:F,$L38)) -> CRUCETAS Y ESTRIADO DEL CARDÁN | G38: =IF($L38=0,"","☐") -> ☐ | H38: =IF($L38=0,"","☐") -> ☐ | L38: =IFERROR(MATCH($L$5&"|"&$C$5&"|11",BD_INSPECCION!$H:$H,0),0) -> 13 | M38: =IF($L38=0,"",INDEX(BD_INSPECCION!D:D,$L38)) -> CARDÁN
B39: =IF($L39=0,"",IF($M39<>$M38,$M39,"")) -> DIFERENCIAL | C39: =IF($L39=0,"",INDEX(BD_INSPECCION!E:E,$L39)) -> INSPECCIONAR | D39: =IF($L39=0,"",INDEX(BD_INSPECCION!F:F,$L39)) -> NIVEL DE ACEITE Y FUGAS | G39: =IF($L39=0,"","☐") -> ☐ | H39: =IF($L39=0,"","☐") -> ☐ | L39: =IFERROR(MATCH($L$5&"|"&$C$5&"|12",BD_INSPECCION!$H:$H,0),0) -> 14 | M39: =IF($L39=0,"",INDEX(BD_INSPECCION!D:D,$L39)) -> DIFERENCIAL
B40: =IF($L40=0,"",IF($M40<>$M39,$M40,"")) | C40: =IF($L40=0,"",INDEX(BD_INSPECCION!E:E,$L40)) -> INSPECCIONAR | D40: =IF($L40=0,"",INDEX(BD_INSPECCION!F:F,$L40)) -> RUIDOS Y RESPIRADERO | G40: =IF($L40=0,"","☐") -> ☐ | H40: =IF($L40=0,"","☐") -> ☐ | L40: =IFERROR(MATCH($L$5&"|"&$C$5&"|13",BD_INSPECCION!$H:$H,0),0) -> 15 | M40: =IF($L40=0,"",INDEX(BD_INSPECCION!D:D,$L40)) -> DIFERENCIAL
B41: =IF($L41=0,"",IF($M41<>$M40,$M41,"")) -> EJES / RODAJES | C41: =IF($L41=0,"",INDEX(BD_INSPECCION!E:E,$L41)) -> INSPECCIONAR | D41: =IF($L41=0,"",INDEX(BD_INSPECCION!F:F,$L41)) -> PALIERES, RODAJES DE RUEDA Y RETENES (JUEGO, RUIDO Y FUGAS) | G41: =IF($L41=0,"","☐") -> ☐ | H41: =IF($L41=0,"","☐") -> ☐ | L41: =IFERROR(MATCH($L$5&"|"&$C$5&"|14",BD_INSPECCION!$H:$H,0),0) -> 16 | M41: =IF($L41=0,"",INDEX(BD_INSPECCION!D:D,$L41)) -> EJES / RODAJES
B42: =IF($L42=0,"",IF($M42<>$M41,$M42,"")) -> FRENOS | C42: =IF($L42=0,"",INDEX(BD_INSPECCION!E:E,$L42)) -> INSPECCIONAR | D42: =IF($L42=0,"",INDEX(BD_INSPECCION!F:F,$L42)) -> ZAPATAS, TAMBORES, CABLES Y JUEGO LIBRE DE PALANCA Y PEDAL | G42: =IF($L42=0,"","☐") -> ☐ | H42: =IF($L42=0,"","☐") -> ☐ | L42: =IFERROR(MATCH($L$5&"|"&$C$5&"|15",BD_INSPECCION!$H:$H,0),0) -> 17 | M42: =IF($L42=0,"",INDEX(BD_INSPECCION!D:D,$L42)) -> FRENOS
B43: =IF($L43=0,"",IF($M43<>$M42,$M43,"")) -> DIRECCIÓN | C43: =IF($L43=0,"",INDEX(BD_INSPECCION!E:E,$L43)) -> INSPECCIONAR | D43: =IF($L43=0,"",INDEX(BD_INSPECCION!F:F,$L43)) -> RODAJES DE DIRECCIÓN Y JUEGO DEL TIMÓN | G43: =IF($L43=0,"","☐") -> ☐ | H43: =IF($L43=0,"","☐") -> ☐ | L43: =IFERROR(MATCH($L$5&"|"&$C$5&"|16",BD_INSPECCION!$H:$H,0),0) -> 18 | M43: =IF($L43=0,"",INDEX(BD_INSPECCION!D:D,$L43)) -> DIRECCIÓN
B44: =IF($L44=0,"",IF($M44<>$M43,$M44,"")) | C44: =IF($L44=0,"",INDEX(BD_INSPECCION!E:E,$L44)) -> LUBRICAR | D44: =IF($L44=0,"",INDEX(BD_INSPECCION!F:F,$L44)) -> RODAJES DE DIRECCIÓN | G44: =IF($L44=0,"","☐") -> ☐ | H44: =IF($L44=0,"","☐") -> ☐ | L44: =IFERROR(MATCH($L$5&"|"&$C$5&"|17",BD_INSPECCION!$H:$H,0),0) -> 19 | M44: =IF($L44=0,"",INDEX(BD_INSPECCION!D:D,$L44)) -> DIRECCIÓN
...

Sheet REGISTRO
B2: FECHA | C2: CÓDIGO | D2: EQUIPO | E2: PLAN | F2: CONTROL | G2: LECTURA (KM / HR) | H2: MANTENIMIENTO REALIZADO | I2: N° OT | J2: TÉCNICO | K2: COSTO PM (S/) | L2: CAMBIOS FUERA DEL PLAN | M2: OBSERVACIONES
D3: =IF(C3="","",IFERROR(VLOOKUP(C3,EQUIPOS!$B$3:$C$18,2,0),"NO EXISTE")) | E3: =IF(C3="","",IFERROR(VLOOKUP(C3,EQUIPOS!$B$3:$F$18,5,0),"")) | F3: =IF(C3="","",IFERROR(VLOOKUP(C3,EQUIPOS!$B$3:$G$18,6,0),"")) | K3: =IF(H3="","",IFERROR(SUMIFS(BD_PLAN!$I$3:$I$312,BD_PLAN!$B$3:$B$312,E3,BD_PLAN!$C$3:$C$312,INDEX(BD_CICLO!$F$3:$F$54,MATCH(E3&"|"&H3,BD_CICLO!$G$3:$G$54,0))),"")) | N3: =IF(C3="","",C3&"|"&COUNTIF(C$3:C3,C3)) | O3: =IF(OR(C3="",M3=""),"",C3&"|"&COUNTIFS(C$3:C3,C3,M$3:M3,"<>"))
D4: =IF(C4="","",IFERROR(VLOOKUP(C4,EQUIPOS!$B$3:$C$18,2,0),"NO EXISTE")) | E4: =IF(C4="","",IFERROR(VLOOKUP(C4,EQUIPOS!$B$3:$F$18,5,0),"")) | F4: =IF(C4="","",IFERROR(VLOOKUP(C4,EQUIPOS!$B$3:$G$18,6,0),"")) | K4: =IF(H4="","",IFERROR(SUMIFS(BD_PLAN!$I$3:$I$312,BD_PLAN!$B$3:$B$312,E4,BD_PLAN!$C$3:$C$312,INDEX(BD_CICLO!$F$3:$F$54,MATCH(E4&"|"&H4,BD_CICLO!$G$3:$G$54,0))),"")) | N4: =IF(C4="","",C4&"|"&COUNTIF(C$3:C4,C4)) | O4: =IF(OR(C4="",M4=""),"",C4&"|"&COUNTIFS(C$3:C4,C4,M$3:M4,"<>"))
D5: =IF(C5="","",IFERROR(VLOOKUP(C5,EQUIPOS!$B$3:$C$18,2,0),"NO EXISTE")) | E5: =IF(C5="","",IFERROR(VLOOKUP(C5,EQUIPOS!$B$3:$F$18,5,0),"")) | F5: =IF(C5="","",IFERROR(VLOOKUP(C5,EQUIPOS!$B$3:$G$18,6,0),"")) | K5: =IF(H5="","",IFERROR(SUMIFS(BD_PLAN!$I$3:$I$312,BD_PLAN!$B$3:$B$312,E5,BD_PLAN!$C$3:$C$312,INDEX(BD_CICLO!$F$3:$F$54,MATCH(E5&"|"&H5,BD_CICLO!$G$3:$G$54,0))),"")) | N5: =IF(C5="","",C5&"|"&COUNTIF(C$3:C5,C5)) | O5: =IF(OR(C5="",M5=""),"",C5&"|"&COUNTIFS(C$3:C5,C5,M$3:M5,"<>"))
D6: =IF(C6="","",IFERROR(VLOOKUP(C6,EQUIPOS!$B$3:$C$18,2,0),"NO EXISTE")) | E6: =IF(C6="","",IFERROR(VLOOKUP(C6,EQUIPOS!$B$3:$F$18,5,0),"")) | F6: =IF(C6="","",IFERROR(VLOOKUP(C6,EQUIPOS!$B$3:$G$18,6,0),"")) | K6: =IF(H6="","",IFERROR(SUMIFS(BD_PLAN!$I$3:$I$312,BD_PLAN!$B$3:$B$312,E6,BD_PLAN!$C$3:$C$312,INDEX(BD_CICLO!$F$3:$F$54,MATCH(E6&"|"&H6,BD_CICLO!$G$3:$G$54,0))),"")) | N6: =IF(C6="","",C6&"|"&COUNTIF(C$3:C6,C6)) | O6: =IF(OR(C6="",M6=""),"",C6&"|"&COUNTIFS(C$3:C6,C6,M$3:M6,"<>"))
D7: =IF(C7="","",IFERROR(VLOOKUP(C7,EQUIPOS!$B$3:$C$18,2,0),"NO EXISTE")) | E7: =IF(C7="","",IFERROR(VLOOKUP(C7,EQUIPOS!$B$3:$F$18,5,0),"")) | F7: =IF(C7="","",IFERROR(VLOOKUP(C7,EQUIPOS!$B$3:$G$18,6,0),"")) | K7: =IF(H7="","",IFERROR(SUMIFS(BD_PLAN!$I$3:$I$312,BD_PLAN!$B$3:$B$312,E7,BD_PLAN!$C$3:$C$312,INDEX(BD_CICLO!$F$3:$F$54,MATCH(E7&"|"&H7,BD_CICLO!$G$3:$G$54,0))),"")) | N7: =IF(C7="","",C7&"|"&COUNTIF(C$3:C7,C7)) | O7: =IF(OR(C7="",M7=""),"",C7&"|"&COUNTIFS(C$3:C7,C7,M$3:M7,"<>"))
D8: =IF(C8="","",IFERROR(VLOOKUP(C8,EQUIPOS!$B$3:$C$18,2,0),"NO EXISTE")) | E8: =IF(C8="","",IFERROR(VLOOKUP(C8,EQUIPOS!$B$3:$F$18,5,0),"")) | F8: =IF(C8="","",IFERROR(VLOOKUP(C8,EQUIPOS!$B$3:$G$18,6,0),"")) | K8: =IF(H8="","",IFERROR(SUMIFS(BD_PLAN!$I$3:$I$312,BD_PLAN!$B$3:$B$312,E8,BD_PLAN!$C$3:$C$312,INDEX(BD_CICLO!$F$3:$F$54,MATCH(E8&"|"&H8,BD_CICLO!$G$3:$G$54,0))),"")) | N8: =IF(C8="","",C8&"|"&COUNTIF(C$3:C8,C8)) | O8: =IF(OR(C8="",M8=""),"",C8&"|"&COUNTIFS(C$3:C8,C8,M$3:M8,"<>"))
D9: =IF(C9="","",IFERROR(VLOOKUP(C9,EQUIPOS!$B$3:$C$18,2,0),"NO EXISTE")) | E9: =IF(C9="","",IFERROR(VLOOKUP(C9,EQUIPOS!$B$3:$F$18,5,0),"")) | F9: =IF(C9="","",IFERROR(VLOOKUP(C9,EQUIPOS!$B$3:$G$18,6,0),"")) | K9: =IF(H9="","",IFERROR(SUMIFS(BD_PLAN!$I$3:$I$312,BD_PLAN!$B$3:$B$312,E9,BD_PLAN!$C$3:$C$312,INDEX(BD_CICLO!$F$3:$F$54,MATCH(E9&"|"&H9,BD_CICLO!$G$3:$G$54,0))),"")) | N9: =IF(C9="","",C9&"|"&COUNTIF(C$3:C9,C9)) | O9: =IF(OR(C9="",M9=""),"",C9&"|"&COUNTIFS(C$3:C9,C9,M$3:M9,"<>"))
D10: =IF(C10="","",IFERROR(VLOOKUP(C10,EQUIPOS!$B$3:$C$18,2,0),"NO EXISTE")) | E10: =IF(C10="","",IFERROR(VLOOKUP(C10,EQUIPOS!$B$3:$F$18,5,0),"")) | F10: =IF(C10="","",IFERROR(VLOOKUP(C10,EQUIPOS!$B$3:$G$18,6,0),"")) | K10: =IF(H10="","",IFERROR(SUMIFS(BD_PLAN!$I$3:$I$312,BD_PLAN!$B$3:$B$312,E10,BD_PLAN!$C$3:$C$312,INDEX(BD_CICLO!$F$3:$F$54,MATCH(E10&"|"&H10,BD_CICLO!$G$3:$G$54,0))),"")) | N10: =IF(C10="","",C10&"|"&COUNTIF(C$3:C10,C10)) | O10: =IF(OR(C10="",M10=""),"",C10&"|"&COUNTIFS(C$3:C10,C10,M$3:M10,"<>"))
D11: =IF(C11="","",IFERROR(VLOOKUP(C11,EQUIPOS!$B$3:$C$18,2,0),"NO EXISTE")) | E11: =IF(C11="","",IFERROR(VLOOKUP(C11,EQUIPOS!$B$3:$F$18,5,0),"")) | F11: =IF(C11="","",IFERROR(VLOOKUP(C11,EQUIPOS!$B$3:$G$18,6,0),"")) | K11: =IF(H11="","",IFERROR(SUMIFS(BD_PLAN!$I$3:$I$312,BD_PLAN!$B$3:$B$312,E11,BD_PLAN!$C$3:$C$312,INDEX(BD_CICLO!$F$3:$F$54,MATCH(E11&"|"&H11,BD_CICLO!$G$3:$G$54,0))),"")) | N11: =IF(C11="","",C11&"|"&COUNTIF(C$3:C11,C11)) | O11: =IF(OR(C11="",M11=""),"",C11&"|"&COUNTIFS(C$3:C11,C11,M$3:M11,"<>"))
D12: =IF(C12="","",IFERROR(VLOOKUP(C12,EQUIPOS!$B$3:$C$18,2,0),"NO EXISTE")) | E12: =IF(C12="","",IFERROR(VLOOKUP(C12,EQUIPOS!$B$3:$F$18,5,0),"")) | F12: =IF(C12="","",IFERROR(VLOOKUP(C12,EQUIPOS!$B$3:$G$18,6,0),"")) | K12: =IF(H12="","",IFERROR(SUMIFS(BD_PLAN!$I$3:$I$312,BD_PLAN!$B$3:$B$312,E12,BD_PLAN!$C$3:$C$312,INDEX(BD_CICLO!$F$3:$F$54,MATCH(E12&"|"&H12,BD_CICLO!$G$3:$G$54,0))),"")) | N12: =IF(C12="","",C12&"|"&COUNTIF(C$3:C12,C12)) | O12: =IF(OR(C12="",M12=""),"",C12&"|"&COUNTIFS(C$3:C12,C12,M$3:M12,"<>"))
